Workbook

Sheet Loss time 05-10
A1: LOSS TIME WHITE WOOD - 05/10/2026
A2: Week | B2: Date (Ngày) | C2: Item's Mã hàng | D2: Code Máy Hư | E2: Q'ty | F2: Số NCR/ME | G2: Khu vực phát sinh/bộ phận hỗ trợ | H2: Code | I2: Name code | J2: Chart / bộ phận chịu trách nhiệm | K2: Lí Do | L2: Ghi chú | M2: From | N2: To | O2: LossTime (Hr) | P2: HC | Q2: Loss time labor (Hrs)
A3: ="W"&WEEKNUM(B3,21) -> W41 | B3: 46300 | G3: RC - WOOD | H3: P20 | I3: Dailly Cleaning | J3: RC WOOD | K3: Vệ sinh khu vực máy móc RC WOOD | M3: 0.29166667 | N3: 0.3125 | O3: =(N3-M3)*24 -> 0.5 | P3: 7 | Q3: =P3*O3 -> 3.5
A4: ="W"&WEEKNUM(B4,21) -> W41 | B4: 46300 | G4: RC - PANEL | H4: P20 | I4: Dailly Cleaning | J4: RC - PANEL | K4: Vệ sinh khu vực máy móc RC PANEL | M4: 0.29166667 | N4: 0.3125 | O4: =(N4-M4)*24 -> 0.5 | P4: 18 | Q4: =P4*O4 -> 9
A5: ="W"&WEEKNUM(B5,21) -> W41 | B5: 46300 | G5: Machining | H5: P20 | I5: Dailly Cleaning | J5: Machining | K5: Vệ sinh khu vực máy móc MAC FINAL | M5: 0.29166667 | N5: 0.3125 | O5: =(N5-M5)*24 -> 0.5 | P5: 7 | Q5: =P5*O5 -> 3.5
A6: ="W"&WEEKNUM(B6,21) -> W41 | B6: 46300 | G6: Machining | H6: P20 | I6: Dailly Cleaning | J6: Machining | K6: Vệ sinh khu vực máy móc PRE MAC | M6: 0.29166667 | N6: 0.3125 | O6: =(N6-M6)*24 -> 0.5 | P6: 12 | Q6: =P6*O6 -> 6
A7: ="W"&WEEKNUM(B7,21) -> W41 | B7: 46300 | G7: Assembly | H7: P20 | I7: Dailly Cleaning | J7: Assembly | K7: Quét nhà toàn xưởng khu vực ASSY | M7: 0.3125 | N7: 0.83333333 | O7: =(N7-M7)*24 -> 12.5 | P7: 2 | Q7: =P7*O7 -> 25
A8: ="W"&WEEKNUM(B8,21) -> W41 | B8: 46300 | G8: RC - PANEL | H8: P26 | I8: Recorder/ Supporter | J8: RC - PANEL | K8: Shop Floor data RC PANEL | L8: Recorder | M8: 0.3125 | N8: 0.83333333 | O8: =(N8-M8)*24 -> 12.5 | P8: 4 | Q8: =P8*O8 -> 50
A9: ="W"&WEEKNUM(B9,21) -> W41 | B9: 46300 | G9: Machining | H9: P26 | I9: Recorder/ Supporter | J9: Machining | K9: Shop Floor data- STOCK ROOM | L9: Recorder | M9: 0.3125 | N9: 0.83333333 | O9: =(N9-M9)*24 -> 12.5 | P9: 1 | Q9: =P9*O9 -> 12.5
A10: ="W"&WEEKNUM(B10,21) -> W41 | B10: 46300 | G10: Machining | H10: P26 | I10: Recorder/ Supporter | J10: Machining | K10: Shop Floor data MAC FINAL | L10: Recorder | M10: 0.3125 | N10: 0.83333333 | O10: =(N10-M10)*24 -> 12.5 | P10: 1 | Q10: =P10*O10 -> 12.5
A11: ="W"&WEEKNUM(B11,21) -> W41 | B11: 46300 | G11: RC - PANEL | H11: P26 | I11: Recorder/ Supporter | J11: RC - PANEL | K11: Theo dõi Hàng venner làm xong | L11: Recorder | M11: 0.3125 | N11: 0.83333333 | O11: =(N11-M11)*24 -> 12.5 | P11: 1 | Q11: =P11*O11 -> 12.5
A12: ="W"&WEEKNUM(B12,21) -> W41 | B12: 46300 | G12: RC - PANEL | H12: P26 | I12: Recorder/ Supporter | J12: RC - PANEL | K12: Nhận venner cho ép nóng | L12: Supporter | M12: 0.3125 | N12: 0.83333333 | O12: =(N12-M12)*24 -> 12.5 | P12: 1 | Q12: =P12*O12 -> 12.5
A13: ="W"&WEEKNUM(B13,21) -> W41 | B13: 46300 | G13: RC - WOOD | H13: P26 | I13: Recorder/ Supporter | J13: RC WOOD | K13: Lựa hàng tinh giao mac- gỗ đẹp xấu | L13: Supporter | M13: 0.3125 | N13: 0.83333333 | O13: =(N13-M13)*24 -> 12.5 | P13: 1 | Q13: =P13*O13 -> 12.5
A14: ="W"&WEEKNUM(B14,21) -> W41 | B14: 46300 | G14: RC - PANEL | H14: P26 | I14: Recorder/ Supporter | J14: RC - PANEL | K14: Ghi nhận hàng giao kho | L14: Recorder | M14: 0.3125 | N14: 0.83333333 | O14: =(N14-M14)*24 -> 12.5 | P14: 1 | Q14: =P14*O14 -> 12.5
A15: ="W"&WEEKNUM(B15,21) -> W41 | B15: 46300 | G15: RC - PANEL | H15: P26 | I15: Recorder/ Supporter | J15: RC - PANEL | K15: Kiểm hàng chất lượng vào kho | L15: Supporter | M15: 0.3125 | N15: 0.83333333 | O15: =(N15-M15)*24 -> 12.5 | P15: 1 | Q15: =P15*O15 -> 12.5
A16: ="W"&WEEKNUM(B16,21) -> W41 | B16: 46300 | G16: RC - PANEL | H16: P26 | I16: Recorder/ Supporter | J16: Machining | K16: Nhận hàng gỗ đầu vào từ RC | L16: Supporter | M16: 0.3125 | N16: 0.83333333 | O16: =(N16-M16)*24 -> 12.5 | P16: 1 | Q16: =P16*O16 -> 12.5
A17: ="W"&WEEKNUM(B17,21) -> W41 | B17: 46300 | G17: Machining | H17: P26 | I17: Recorder/ Supporter | J17: Machining | K17: Ghi nhận hàng giao kho | L17: Recorder | M17: 0.3125 | N17: 0.83333333 | O17: =(N17-M17)*24 -> 12.5 | P17: 1 | Q17: =P17*O17 -> 12.5
A18: ="W"&WEEKNUM(B18,21) -> W41 | B18: 46300 | G18: Machining | H18: P26 | I18: Recorder/ Supporter | J18: Machining | K18: quét nhà toàn xưởng khu vực ASSY | L18: Supporter | M18: 0.3125 | N18: 0.83333333 | O18: =(N18-M18)*24 -> 12.5 | P18: 1 | Q18: =P18*O18 -> 12.5
A19: ="W"&WEEKNUM(B19,21) -> W41 | B19: 46300 | G19: Machining | H19: P26 | I19: Recorder/ Supporter | J19: Machining | K19: Theo hàng pilot -hàng test-spo-subcon-NCR | L19: Recorder | M19: 0.3125 | N19: 0.83333333 | O19: =(N19-M19)*24 -> 12.5 | P19: 1 | Q19: =P19*O19 -> 12.5
... A22: ="W"&WEEKNUM(B22,21) -> W41 | B22: 46300 | G22: Assembly | H22: P26 | I22: Recorder/ Supporter | J22: Assembly | K22: Giao nhận HW- phát HW cho Line sx | L22: Supporter | M22: 0.3125 | N22: 0.83333333 | O22: =(N22-M22)*24 -> 12.5 | P22: 1 | Q22: =P22*O22 -> 12.5
A23: ="W"&WEEKNUM(B23,21) -> W41 | B23: 46300 | G23: Assembly | H23: P22 | I23: HR Training New Workers | J23: HR/HSE | K23: Đào tạo công nhân mới | M23: 0.33333333 | N23: 0.66666667 | O23: =(N23-M23)*24 -> 8 | P23: 6 | Q23: =P23*O23 -> 48
A24: ="W"&WEEKNUM(B24,21) -> W41 | B24: 46300 | G24: Assembly | H24: A2 | I24: Training | J24: HR/HSE | K24: HC mới- 50% hiệu suất- 2 tuần-18/9 | L24: A2 ngày 5/12 - nhóm 18/9 | M24: 0.3125 | N24: 0.5 | O24: =(N24-M24)*24 -> 4.5 | P24: 7 | Q24: =P24*O24 -> 31.5
A25: ="W"&WEEKNUM(B25,21) -> W41 | B25: 46300 | G25: Assembly | H25: A2 | I25: Training | J25: HR/HSE | K25: HC mới- 50% hiệu suất- 2 tuần-23/9 | L25: A2 ngày 10/12 - nhóm 23/9 | M25: 0.3125 | N25: 0.5 | O25: =(N25-M25)*24 -> 4.5 | P25: 3 | Q25: =P25*O25 -> 13.5
A26: ="W"&WEEKNUM(B26,21) -> W41 | B26: 46300 | G26: Assembly | H26: A2 | I26: Training | J26: HR/HSE | K26: HC mới- 50% hiệu suất- 2 tuần-24/9 | L26: A2 ngày 5/12 - nhóm 24/9 | M26: 0.3125 | N26: 0.5 | O26: =(N26-M26)*24 -> 4.5 | P26: 5 | Q26: =P26*O26 -> 22.5
A27: ="W"&WEEKNUM(B27,21) -> W41 | B27: 46300 | G27: Assembly | H27: A2 | I27: Training | J27: HR/HSE | K27: HC mới- 50% hiệu suất- 2 tuần-25/9 | L27: A2 ngày 5/12 - nhóm 25/9 | M27: 0.3125 | N27: 0.5 | O27: =(N27-M27)*24 -> 4.5 | P27: 1 | Q27: =P27*O27 -> 4.5
A28: ="W"&WEEKNUM(B28,21) -> W41 | B28: 46300 | G28: Assembly | H28: A2 | I28: Training | J28: HR/HSE | K28: HC mới- 50% hiệu suất- 2 tuần-28/9 | L28: A2 ngày 6/12 - nhóm 28/9 | M28: 0.3125 | N28: 0.5 | O28: =(N28-M28)*24 -> 4.5 | P28: 3 | Q28: =P28*O28 -> 13.5
A29: ="W"&WEEKNUM(B29,21) -> W41 | B29: 46300 | G29: Machining | H29: A2 | I29: Training | J29: HR/HSE | K29: HC mới- 50% hiệu suất- 2 tuần-21/9 | L29: A2 ngày 5/12 - nhóm 21/9 | M29: 0.3125 | N29: 0.5 | O29: =(N29-M29)*24 -> 4.5 | P29: 2 | Q29: =P29*O29 -> 9
A30: ="W"&WEEKNUM(B30,21) -> W41 | B30: 46300 | G30: Machining | H30: A2 | I30: Training | J30: HR/HSE | K30: HC mới- 50% hiệu suất- 2 tuần-22/9 | L30: A2 ngày 5/12 - nhóm 22/9 | M30: 0.3125 | N30: 0.5 | O30: =(N30-M30)*24 -> 4.5 | P30: 4 | Q30: =P30*O30 -> 18
A31: ="W"&WEEKNUM(B31,21) -> W41 | B31: 46300 | G31: Machining | H31: A2 | I31: Training | J31: HR/HSE | K31: HC mới- 50% hiệu suất- 2 tuần-23/9 | L31: A2 ngày 10/12 - nhóm 23/9 | M31: 0.3125 | N31: 0.5 | O31: =(N31-M31)*24 -> 4.5 | P31: 9 | Q31: =P31*O31 -> 40.5
A32: ="W"&WEEKNUM(B32,21) -> W41 | B32: 46300 | G32: Machining | H32: A2 | I32: Training | J32: HR/HSE | K32: HC mới- 50% hiệu suất- 2 tuần-24/9 | L32: A2 ngày 5/12 - nhóm 24/9 | M32: 0.3125 | N32: 0.5 | O32: =(N32-M32)*24 -> 4.5 | P32: 3 | Q32: =P32*O32 -> 13.5
A33: ="W"&WEEKNUM(B33,21) -> W41 | B33: 46300 | G33: Machining | H33: A2 | I33: Training | J33: HR/HSE | K33: HC mới- 50% hiệu suất- 2 tuần-25/9 | L33: A2 ngày 5/12 - nhóm 25/9 | M33: 0.3125 | N33: 0.5 | O33: =(N33-M33)*24 -> 4.5 | P33: 1 | Q33: =P33*O33 -> 4.5
A34: ="W"&WEEKNUM(B34,21) -> W41 | B34: 46300 | G34: RC | H34: A2 | I34: Training | J34: HR/HSE | K34: HC mới- 50% hiệu suất- 2 tuần-22/9 | L34: A2 ngày 5/12 - nhóm 22/9 | M34: 0.3125 | N34: 0.5 | O34: =(N34-M34)*24 -> 4.5 | P34: 1 | Q34: =P34*O34 -> 4.5
A35: ="W"&WEEKNUM(B35,21) -> W41 | B35: 46300 | G35: RC | H35: A2 | I35: Training | J35: HR/HSE | K35: HC mới- 50% hiệu suất- 2 tuần-23/9 | L35: A2 ngày 5/12 - nhóm 23/9 | M35: 0.3125 | N35: 0.5 | O35: =(N35-M35)*24 -> 4.5 | P35: 1 | Q35: =P35*O35 -> 4.5
... A39: ="W"&WEEKNUM(B39,21) -> W41 | B39: 46300 | G39: Raw Cutting Panel | H39: A2 | I39: Training | J39: HR/HSE | K39: HC mới- 50% hiệu suất- 2 tuần-25/9 | L39: A2 ngày 4/12 - nhóm 25/9 | M39: 0.3125 | N39: 0.5 | O39: =(N39-M39)*24 -> 4.5 | P39: 1 | Q39: =P39*O39 -> 4.5
P40: Tổng | Q40: =SUM(Q3:Q39) -> 531.5
A42: Vàng = nhân viên mới ngày đầu (P22). Xanh = nhân viên đang ghi A2 (cột Ghi chú cho biết ngày thứ mấy trong 12 ngày).

Sheet Loss time 06-10
A1: LOSS TIME WHITE WOOD - 06/10/2026
A2: Week | B2: Date (Ngày) | C2: Item's Mã hàng | D2: Code Máy Hư | E2: Q'ty | F2: Số NCR/ME | G2: Khu vực phát sinh/bộ phận hỗ trợ | H2: Code | I2: Name code | J2: Chart / bộ phận chịu trách nhiệm | K2: Lí Do | L2: Ghi chú | M2: From | N2: To | O2: LossTime (Hr) | P2: HC | Q2: Loss time labor (Hrs)
A3: ="W"&WEEKNUM(B3,21) -> W41 | B3: 46301 | G3: RC - WOOD | H3: P20 | I3: Dailly Cleaning | J3: RC WOOD | K3: Vệ sinh khu vực máy móc RC WOOD | M3: 0.29166667 | N3: 0.3125 | O3: =(N3-M3)*24 -> 0.5 | P3: 7 | Q3: =P3*O3 -> 3.5
A4: ="W"&WEEKNUM(B4,21) -> W41 | B4: 46301 | G4: RC - PANEL | H4: P20 | I4: Dailly Cleaning | J4: RC - PANEL | K4: Vệ sinh khu vực máy móc RC PANEL | M4: 0.29166667 | N4: 0.3125 | O4: =(N4-M4)*24 -> 0.5 | P4: 18 | Q4: =P4*O4 -> 9
A5: ="W"&WEEKNUM(B5,21) -> W41 | B5: 46301 | G5: Machining | H5: P20 | I5: Dailly Cleaning | J5: Machining | K5: Vệ sinh khu vực máy móc MAC FINAL | M5: 0.29166667 | N5: 0.3125 | O5: =(N5-M5)*24 -> 0.5 | P5: 7 | Q5: =P5*O5 -> 3.5
A6: ="W"&WEEKNUM(B6,21) -> W41 | B6: 46301 | G6: Machining | H6: P20 | I6: Dailly Cleaning | J6: Machining | K6: Vệ sinh khu vực máy móc PRE MAC | M6: 0.29166667 | N6: 0.3125 | O6: =(N6-M6)*24 -> 0.5 | P6: 12 | Q6: =P6*O6 -> 6
A7: ="W"&WEEKNUM(B7,21) -> W41 | B7: 46301 | G7: Assembly | H7: P20 | I7: Dailly Cleaning | J7: Assembly | K7: Quét nhà toàn xưởng khu vực ASSY | M7: 0.3125 | N7: 0.83333333 | O7: =(N7-M7)*24 -> 12.5 | P7: 2 | Q7: =P7*O7 -> 25
A8: ="W"&WEEKNUM(B8,21) -> W41 | B8: 46301 | G8: RC - PANEL | H8: P26 | I8: Recorder/ Supporter | J8: RC - PANEL | K8: Shop Floor data RC PANEL | L8: Recorder | M8: 0.3125 | N8: 0.83333333 | O8: =(N8-M8)*24 -> 12.5 | P8: 4 | Q8: =P8*O8 -> 50
A9: ="W"&WEEKNUM(B9,21) -> W41 | B9: 46301 | G9: Machining | H9: P26 | I9: Recorder/ Supporter | J9: Machining | K9: Shop Floor data- STOCK ROOM | L9: Recorder | M9: 0.3125 | N9: 0.83333333 | O9: =(N9-M9)*24 -> 12.5 | P9: 1 | Q9: =P9*O9 -> 12.5
A10: ="W"&WEEKNUM(B10,21) -> W41 | B10: 46301 | G10: Machining | H10: P26 | I10: Recorder/ Supporter | J10: Machining | K10: Shop Floor data MAC FINAL | L10: Recorder | M10: 0.3125 | N10: 0.83333333 | O10: =(N10-M10)*24 -> 12.5 | P10: 1 | Q10: =P10*O10 -> 12.5
A11: ="W"&WEEKNUM(B11,21) -> W41 | B11: 46301 | G11: RC - PANEL | H11: P26 | I11: Recorder/ Supporter | J11: RC - PANEL | K11: Theo dõi Hàng venner làm xong | L11: Recorder | M11: 0.3125 | N11: 0.83333333 | O11: =(N11-M11)*24 -> 12.5 | P11: 1 | Q11: =P11*O11 -> 12.5
A12: ="W"&WEEKNUM(B12,21) -> W41 | B12: 46301 | G12: RC - PANEL | H12: P26 | I12: Recorder/ Supporter | J12: RC - PANEL | K12: Nhận venner cho ép nóng | L12: Supporter | M12: 0.3125 | N12: 0.83333333 | O12: =(N12-M12)*24 -> 12.5 | P12: 1 | Q12: =P12*O12 -> 12.5
A13: ="W"&WEEKNUM(B13,21) -> W41 | B13: 46301 | G13: RC - WOOD | H13: P26 | I13: Recorder/ Supporter | J13: RC WOOD | K13: Lựa hàng tinh giao mac- gỗ đẹp xấu | L13: Supporter | M13: 0.3125 | N13: 0.83333333 | O13: =(N13-M13)*24 -> 12.5 | P13: 1 | Q13: =P13*O13 -> 12.5
A14: ="W"&WEEKNUM(B14,21) -> W41 | B14: 46301 | G14: RC - PANEL | H14: P26 | I14: Recorder/ Supporter | J14: RC - PANEL | K14: Ghi nhận hàng giao kho | L14: Recorder | M14: 0.3125 | N14: 0.83333333 | O14: =(N14-M14)*24 -> 12.5 | P14: 1 | Q14: =P14*O14 -> 12.5
A15: ="W"&WEEKNUM(B15,21) -> W41 | B15: 46301 | G15: RC - PANEL | H15: P26 | I15: Recorder/ Supporter | J15: RC - PANEL | K15: Kiểm hàng chất lượng vào kho | L15: Supporter | M15: 0.3125 | N15: 0.83333333 | O15: =(N15-M15)*24 -> 12.5 | P15: 1 | Q15: =P15*O15 -> 12.5
A16: ="W"&WEEKNUM(B16,21) -> W41 | B16: 46301 | G16: RC - PANEL | H16: P26 | I16: Recorder/ Supporter | J16: Machining | K16: Nhận hàng gỗ đầu vào từ RC | L16: Supporter | M16: 0.3125 | N16: 0.83333333 | O16: =(N16-M16)*24 -> 12.5 | P16: 1 | Q16: =P16*O16 -> 12.5
A17: ="W"&WEEKNUM(B17,21) -> W41 | B17: 46301 | G17: Machining | H17: P26 | I17: Recorder/ Supporter | J17: Machining | K17: Ghi nhận hàng giao kho | L17: Recorder | M17: 0.3125 | N17: 0.83333333 | O17: =(N17-M17)*24 -> 12.5 | P17: 1 | Q17: =P17*O17 -> 12.5
A18: ="W"&WEEKNUM(B18,21) -> W41 | B18: 46301 | G18: Machining | H18: P26 | I18: Recorder/ Supporter | J18: Machining | K18: quét nhà toàn xưởng khu vực ASSY | L18: Supporter | M18: 0.3125 | N18: 0.83333333 | O18: =(N18-M18)*24 -> 12.5 | P18: 1 | Q18: =P18*O18 -> 12.5
A19: ="W"&WEEKNUM(B19,21) -> W41 | B19: 46301 | G19: Machining | H19: P26 | I19: Recorder/ Supporter | J19: Machining | K19: Theo hàng pilot -hàng test-spo-subcon-NCR | L19: Recorder | M19: 0.3125 | N19: 0.83333333 | O19: =(N19-M19)*24 -> 12.5 | P19: 1 | Q19: =P19*O19 -> 12.5
... A22: ="W"&WEEKNUM(B22,21) -> W41 | B22: 46301 | G22: Assembly | H22: P26 | I22: Recorder/ Supporter | J22: Assembly | K22: Giao nhận HW- phát HW cho Line sx | L22: Supporter | M22: 0.3125 | N22: 0.83333333 | O22: =(N22-M22)*24 -> 12.5 | P22: 1 | Q22: =P22*O22 -> 12.5
A23: ="W"&WEEKNUM(B23,21) -> W41 | B23: 46301 | G23: Assembly | H23: P22 | I23: HR Training New Workers | J23: HR/HSE | K23: Đào tạo công nhân mới | M23: 0.33333333 | N23: 0.66666667 | O23: =(N23-M23)*24 -> 8 | P23: 7 | Q23: =P23*O23 -> 56
A24: ="W"&WEEKNUM(B24,21) -> W41 | B24: 46301 | G24: Raw Cutting Panel | H24: P22 | I24: HR Training New Workers | J24: HR/HSE | K24: Đào tạo công nhân mới | M24: 0.33333333 | N24: 0.66666667 | O24: =(N24-M24)*24 -> 8 | P24: 4 | Q24: =P24*O24 -> 32
A25: ="W"&WEEKNUM(B25,21) -> W41 | B25: 46301 | G25: Machining | H25: P22 | I25: HR Training New Workers | J25: HR/HSE | K25: Đào tạo công nhân mới | M25: 0.33333333 | N25: 0.66666667 | O25: =(N25-M25)*24 -> 8 | P25: 3 | Q25: =P25*O25 -> 24
A26: ="W"&WEEKNUM(B26,21) -> W41 | B26: 46301 | G26: Assembly | H26: A2 | I26: Training | J26: HR/HSE | K26: HC mới- 50% hiệu suất- 2 tuần-18/9 | L26: A2 ngày 6/12 - nhóm 18/9 | M26: 0.3125 | N26: 0.5 | O26: =(N26-M26)*24 -> 4.5 | P26: 7 | Q26: =P26*O26 -> 31.5
A27: ="W"&WEEKNUM(B27,21) -> W41 | B27: 46301 | G27: Assembly | H27: A2 | I27: Training | J27: HR/HSE | K27: HC mới- 50% hiệu suất- 2 tuần-23/9 | L27: A2 ngày 11/12 - nhóm 23/9 | M27: 0.3125 | N27: 0.5 | O27: =(N27-M27)*24 -> 4.5 | P27: 3 | Q27: =P27*O27 -> 13.5
A28: ="W"&WEEKNUM(B28,21) -> W41 | B28: 46301 | G28: Assembly | H28: A2 | I28: Training | J28: HR/HSE | K28: HC mới- 50% hiệu suất- 2 tuần-24/9 | L28: A2 ngày 6/12 - nhóm 24/9 | M28: 0.3125 | N28: 0.5 | O28: =(N28-M28)*24 -> 4.5 | P28: 5 | Q28: =P28*O28 -> 22.5
A29: ="W"&WEEKNUM(B29,21) -> W41 | B29: 46301 | G29: Assembly | H29: A2 | I29: Training | J29: HR/HSE | K29: HC mới- 50% hiệu suất- 2 tuần-25/9 | L29: A2 ngày 6/12 - nhóm 25/9 | M29: 0.3125 | N29: 0.5 | O29: =(N29-M29)*24 -> 4.5 | P29: 1 | Q29: =P29*O29 -> 4.5
A30: ="W"&WEEKNUM(B30,21) -> W41 | B30: 46301 | G30: Assembly | H30: A2 | I30: Training | J30: HR/HSE | K30: HC mới- 50% hiệu suất- 2 tuần-28/9 | L30: A2 ngày 7/12 - nhóm 28/9 | M30: 0.3125 | N30: 0.5 | O30: =(N30-M30)*24 -> 4.5 | P30: 3 | Q30: =P30*O30 -> 13.5
A31: ="W"&WEEKNUM(B31,21) -> W41 | B31: 46301 | G31: Machining | H31: A2 | I31: Training | J31: HR/HSE | K31: HC mới- 50% hiệu suất- 2 tuần-21/9 | L31: A2 ngày 6/12 - nhóm 21/9 | M31: 0.3125 | N31: 0.5 | O31: =(N31-M31)*24 -> 4.5 | P31: 2 | Q31: =P31*O31 -> 9
A32: ="W"&WEEKNUM(B32,21) -> W41 | B32: 46301 | G32: Machining | H32: A2 | I32: Training | J32: HR/HSE | K32: HC mới- 50% hiệu suất- 2 tuần-22/9 | L32: A2 ngày 6/12 - nhóm 22/9 | M32: 0.3125 | N32: 0.5 | O32: =(N32-M32)*24 -> 4.5 | P32: 4 | Q32: =P32*O32 -> 18
A33: ="W"&WEEKNUM(B33,21) -> W41 | B33: 46301 | G33: Machining | H33: A2 | I33: Training | J33: HR/HSE | K33: HC mới- 50% hiệu suất- 2 tuần-23/9 | L33: A2 ngày 11/12 - nhóm 23/9 | M33: 0.3125 | N33: 0.5 | O33: =(N33-M33)*24 -> 4.5 | P33: 9 | Q33: =P33*O33 -> 40.5
A34: ="W"&WEEKNUM(B34,21) -> W41 | B34: 46301 | G34: Machining | H34: A2 | I34: Training | J34: HR/HSE | K34: HC mới- 50% hiệu suất- 2 tuần-24/9 | L34: A2 ngày 6/12 - nhóm 24/9 | M34: 0.3125 | N34: 0.5 | O34: =(N34-M34)*24 -> 4.5 | P34: 3 | Q34: =P34*O34 -> 13.5
A35: ="W"&WEEKNUM(B35,21) -> W41 | B35: 46301 | G35: Machining | H35: A2 | I35: Training | J35: HR/HSE | K35: HC mới- 50% hiệu suất- 2 tuần-25/9 | L35: A2 ngày 6/12 - nhóm 25/9 | M35: 0.3125 | N35: 0.5 | O35: =(N35-M35)*24 -> 4.5 | P35: 1 | Q35: =P35*O35 -> 4.5
A36: ="W"&WEEKNUM(B36,21) -> W41 | B36: 46301 | G36: RC | H36: A2 | I36: Training | J36: HR/HSE | K36: HC mới- 50% hiệu suất- 2 tuần-22/9 | L36: A2 ngày 6/12 - nhóm 22/9 | M36: 0.3125 | N36: 0.5 | O36: =(N36-M36)*24 -> 4.5 | P36: 1 | Q36: =P36*O36 -> 4.5
A37: ="W"&WEEKNUM(B37,21) -> W41 | B37: 46301 | G37: RC | H37: A2 | I37: Training | J37: HR/HSE | K37: HC mới- 50% hiệu suất- 2 tuần-23/9 | L37: A2 ngày 6/12 - nhóm 23/9 | M37: 0.3125 | N37: 0.5 | O37: =(N37-M37)*24 -> 4.5 | P37: 1 | Q37: =P37*O37 -> 4.5
... A42: ="W"&WEEKNUM(B42,21) -> W41 | B42: 46301 | G42: Assembly | H42: A2 | I42: Training | J42: HR/HSE | K42: HC mới- 50% hiệu suất- 2 tuần-05/10 | L42: A2 ngày 1/12 - nhóm 05/10 | M42: 0.3125 | N42: 0.5 | O42: =(N42-M42)*24 -> 4.5 | P42: 6 | Q42: =P42*O42 -> 27
P43: Tổng | Q43: =SUM(Q3:Q42) -> 622.5
A45: Vàng = nhân viên mới ngày đầu (P22). Xanh = nhân viên đang ghi A2 (cột Ghi chú cho biết ngày thứ mấy trong 12 ngày).

Sheet Loss time 07-10
A1: LOSS TIME WHITE WOOD - 07/10/2026
A2: Week | B2: Date (Ngày) | C2: Item's Mã hàng | D2: Code Máy Hư | E2: Q'ty | F2: Số NCR/ME | G2: Khu vực phát sinh/bộ phận hỗ trợ | H2: Code | I2: Name code | J2: Chart / bộ phận chịu trách nhiệm | K2: Lí Do | L2: Ghi chú | M2: From | N2: To | O2: LossTime (Hr) | P2: HC | Q2: Loss time labor (Hrs)
A3: ="W"&WEEKNUM(B3,21) -> W41 | B3: 46302 | G3: RC - WOOD | H3: P20 | I3: Dailly Cleaning | J3: RC WOOD | K3: Vệ sinh khu vực máy móc RC WOOD | M3: 0.29166667 | N3: 0.3125 | O3: =(N3-M3)*24 -> 0.5 | P3: 7 | Q3: =P3*O3 -> 3.5
A4: ="W"&WEEKNUM(B4,21) -> W41 | B4: 46302 | G4: RC - PANEL | H4: P20 | I4: Dailly Cleaning | J4: RC - PANEL | K4: Vệ sinh khu vực máy móc RC PANEL | M4: 0.29166667 | N4: 0.3125 | O4: =(N4-M4)*24 -> 0.5 | P4: 18 | Q4: =P4*O4 -> 9
A5: ="W"&WEEKNUM(B5,21) -> W41 | B5: 46302 | G5: Machining | H5: P20 | I5: Dailly Cleaning | J5: Machining | K5: Vệ sinh khu vực máy móc MAC FINAL | M5: 0.29166667 | N5: 0.3125 | O5: =(N5-M5)*24 -> 0.5 | P5: 7 | Q5: =P5*O5 -> 3.5
A6: ="W"&WEEKNUM(B6,21) -> W41 | B6: 46302 | G6: Machining | H6: P20 | I6: Dailly Cleaning | J6: Machining | K6: Vệ sinh khu vực máy móc PRE MAC | M6: 0.29166667 | N6: 0.3125 | O6: =(N6-M6)*24 -> 0.5 | P6: 12 | Q6: =P6*O6 -> 6
A7: ="W"&WEEKNUM(B7,21) -> W41 | B7: 46302 | G7: Assembly | H7: P20 | I7: Dailly Cleaning | J7: Assembly | K7: Quét nhà toàn xưởng khu vực ASSY | M7: 0.3125 | N7: 0.83333333 | O7: =(N7-M7)*24 -> 12.5 | P7: 2 | Q7: =P7*O7 -> 25
A8: ="W"&WEEKNUM(B8,21) -> W41 | B8: 46302 | G8: RC - PANEL | H8: P26 | I8: Recorder/ Supporter | J8: RC - PANEL | K8: Shop Floor data RC PANEL | L8: Recorder | M8: 0.3125 | N8: 0.83333333 | O8: =(N8-M8)*24 -> 12.5 | P8: 4 | Q8: =P8*O8 -> 50
A9: ="W"&WEEKNUM(B9,21) -> W41 | B9: 46302 | G9: Machining | H9: P26 | I9: Recorder/ Supporter | J9: Machining | K9: Shop Floor data- STOCK ROOM | L9: Recorder | M9: 0.3125 | N9: 0.83333333 | O9: =(N9-M9)*24 -> 12.5 | P9: 1 | Q9: =P9*O9 -> 12.5
A10: ="W"&WEEKNUM(B10,21) -> W41 | B10: 46302 | G10: Machining | H10: P26 | I10: Recorder/ Supporter | J10: Machining | K10: Shop Floor data MAC FINAL | L10: Recorder | M10: 0.3125 | N10: 0.83333333 | O10: =(N10-M10)*24 -> 12.5 | P10: 1 | Q10: =P10*O10 -> 12.5
A11: ="W"&WEEKNUM(B11,21) -> W41 | B11: 46302 | G11: RC - PANEL | H11: P26 | I11: Recorder/ Supporter | J11: RC - PANEL | K11: Theo dõi Hàng venner làm xong | L11: Recorder | M11: 0.3125 | N11: 0.83333333 | O11: =(N11-M11)*24 -> 12.5 | P11: 1 | Q11: =P11*O11 -> 12.5
A12: ="W"&WEEKNUM(B12,21) -> W41 | B12: 46302 | G12: RC - PANEL | H12: P26 | I12: Recorder/ Supporter | J12: RC - PANEL | K12: Nhận venner cho ép nóng | L12: Supporter | M12: 0.3125 | N12: 0.83333333 | O12: =(N12-M12)*24 -> 12.5 | P12: 1 | Q12: =P12*O12 -> 12.5
A13: ="W"&WEEKNUM(B13,21) -> W41 | B13: 46302 | G13: RC - WOOD | H13: P26 | I13: Recorder/ Supporter | J13: RC WOOD | K13: Lựa hàng tinh giao mac- gỗ đẹp xấu | L13: Supporter | M13: 0.3125 | N13: 0.83333333 | O13: =(N13-M13)*24 -> 12.5 | P13: 1 | Q13: =P13*O13 -> 12.5
A14: ="W"&WEEKNUM(B14,21) -> W41 | B14: 46302 | G14: RC - PANEL | H14: P26 | I14: Recorder/ Supporter | J14: RC - PANEL | K14: Ghi nhận hàng giao kho | L14: Recorder | M14: 0.3125 | N14: 0.83333333 | O14: =(N14-M14)*24 -> 12.5 | P14: 1 | Q14: =P14*O14 -> 12.5
A15: ="W"&WEEKNUM(B15,21) -> W41 | B15: 46302 | G15: RC - PANEL | H15: P26 | I15: Recorder/ Supporter | J15: RC - PANEL | K15: Kiểm hàng chất lượng vào kho | L15: Supporter | M15: 0.3125 | N15: 0.83333333 | O15: =(N15-M15)*24 -> 12.5 | P15: 1 | Q15: =P15*O15 -> 12.5
A16: ="W"&WEEKNUM(B16,21) -> W41 | B16: 46302 | G16: RC - PANEL | H16: P26 | I16: Recorder/ Supporter | J16: Machining | K16: Nhận hàng gỗ đầu vào từ RC | L16: Supporter | M16: 0.3125 | N16: 0.83333333 | O16: =(N16-M16)*24 -> 12.5 | P16: 1 | Q16: =P16*O16 -> 12.5
A17: ="W"&WEEKNUM(B17,21) -> W41 | B17: 46302 | G17: Machining | H17: P26 | I17: Recorder/ Supporter | J17: Machining | K17: Ghi nhận hàng giao kho | L17: Recorder | M17: 0.3125 | N17: 0.83333333 | O17: =(N17-M17)*24 -> 12.5 | P17: 1 | Q17: =P17*O17 -> 12.5
A18: ="W"&WEEKNUM(B18,21) -> W41 | B18: 46302 | G18: Machining | H18: P26 | I18: Recorder/ Supporter | J18: Machining | K18: quét nhà toàn xưởng khu vực ASSY | L18: Supporter | M18: 0.3125 | N18: 0.83333333 | O18: =(N18-M18)*24 -> 12.5 | P18: 1 | Q18: =P18*O18 -> 12.5
A19: ="W"&WEEKNUM(B19,21) -> W41 | B19: 46302 | G19: Machining | H19: P26 | I19: Recorder/ Supporter | J19: Machining | K19: Theo hàng pilot -hàng test-spo-subcon-NCR | L19: Recorder | M19: 0.3125 | N19: 0.83333333 | O19: =(N19-M19)*24 -> 12.5 | P19: 1 | Q19: =P19*O19 -> 12.5
... A22: ="W"&WEEKNUM(B22,21) -> W41 | B22: 46302 | G22: Assembly | H22: P26 | I22: Recorder/ Supporter | J22: Assembly | K22: Giao nhận HW- phát HW cho Line sx | L22: Supporter | M22: 0.3125 | N22: 0.83333333 | O22: =(N22-M22)*24 -> 12.5 | P22: 1 | Q22: =P22*O22 -> 12.5
A23: ="W"&WEEKNUM(B23,21) -> W41 | B23: 46302 | G23: Assembly | H23: P22 | I23: HR Training New Workers | J23: HR/HSE | K23: Đào tạo công nhân mới | M23: 0.33333333 | N23: 0.66666667 | O23: =(N23-M23)*24 -> 8 | P23: 6 | Q23: =P23*O23 -> 48
A24: ="W"&WEEKNUM(B24,21) -> W41 | B24: 46302 | G24: Raw Cutting Panel | H24: P22 | I24: HR Training New Workers | J24: HR/HSE | K24: Đào tạo công nhân mới | M24: 0.33333333 | N24: 0.66666667 | O24: =(N24-M24)*24 -> 8 | P24: 2 | Q24: =P24*O24 -> 16
A25: ="W"&WEEKNUM(B25,21) -> W41 | B25: 46302 | G25: Assembly | H25: A2 | I25: Training | J25: HR/HSE | K25: HC mới- 50% hiệu suất- 2 tuần-18/9 | L25: A2 ngày 7/12 - nhóm 18/9 | M25: 0.3125 | N25: 0.5 | O25: =(N25-M25)*24 -> 4.5 | P25: 7 | Q25: =P25*O25 -> 31.5
A26: ="W"&WEEKNUM(B26,21) -> W41 | B26: 46302 | G26: Assembly | H26: A2 | I26: Training | J26: HR/HSE | K26: HC mới- 50% hiệu suất- 2 tuần-23/9 | L26: A2 ngày 12/12 - nhóm 23/9 | M26: 0.3125 | N26: 0.5 | O26: =(N26-M26)*24 -> 4.5 | P26: 3 | Q26: =P26*O26 -> 13.5
A27: ="W"&WEEKNUM(B27,21) -> W41 | B27: 46302 | G27: Assembly | H27: A2 | I27: Training | J27: HR/HSE | K27: HC mới- 50% hiệu suất- 2 tuần-24/9 | L27: A2 ngày 7/12 - nhóm 24/9 | M27: 0.3125 | N27: 0.5 | O27: =(N27-M27)*24 -> 4.5 | P27: 5 | Q27: =P27*O27 -> 22.5
A28: ="W"&WEEKNUM(B28,21) -> W41 | B28: 46302 | G28: Assembly | H28: A2 | I28: Training | J28: HR/HSE | K28: HC mới- 50% hiệu suất- 2 tuần-25/9 | L28: A2 ngày 7/12 - nhóm 25/9 | M28: 0.3125 | N28: 0.5 | O28: =(N28-M28)*24 -> 4.5 | P28: 1 | Q28: =P28*O28 -> 4.5
A29: ="W"&WEEKNUM(B29,21) -> W41 | B29: 46302 | G29: Assembly | H29: A2 | I29: Training | J29: HR/HSE | K29: HC mới- 50% hiệu suất- 2 tuần-28/9 | L29: A2 ngày 8/12 - nhóm 28/9 | M29: 0.3125 | N29: 0.5 | O29: =(N29-M29)*24 -> 4.5 | P29: 3 | Q29: =P29*O29 -> 13.5
A30: ="W"&WEEKNUM(B30,21) -> W41 | B30: 46302 | G30: Machining | H30: A2 | I30: Training | J30: HR/HSE | K30: HC mới- 50% hiệu suất- 2 tuần-21/9 | L30: A2 ngày 7/12 - nhóm 21/9 | M30: 0.3125 | N30: 0.5 | O30: =(N30-M30)*24 -> 4.5 | P30: 2 | Q30: =P30*O30 -> 9
A31: ="W"&WEEKNUM(B31,21) -> W41 | B31: 46302 | G31: Machining | H31: A2 | I31: Training | J31: HR/HSE | K31: HC mới- 50% hiệu suất- 2 tuần-22/9 | L31: A2 ngày 7/12 - nhóm 22/9 | M31: 0.3125 | N31: 0.5 | O31: =(N31-M31)*24 -> 4.5 | P31: 4 | Q31: =P31*O31 -> 18
A32: ="W"&WEEKNUM(B32,21) -> W41 | B32: 46302 | G32: Machining | H32: A2 | I32: Training | J32: HR/HSE | K32: HC mới- 50% hiệu suất- 2 tuần-23/9 | L32: A2 ngày 12/12 - nhóm 23/9 | M32: 0.3125 | N32: 0.5 | O32: =(N32-M32)*24 -> 4.5 | P32: 9 | Q32: =P32*O32 -> 40.5
A33: ="W"&WEEKNUM(B33,21) -> W41 | B33: 46302 | G33: Machining | H33: A2 | I33: Training | J33: HR/HSE | K33: HC mới- 50% hiệu suất- 2 tuần-24/9 | L33: A2 ngày 7/12 - nhóm 24/9 | M33: 0.3125 | N33: 0.5 | O33: =(N33-M33)*24 -> 4.5 | P33: 3 | Q33: =P33*O33 -> 13.5
A34: ="W"&WEEKNUM(B34,21) -> W41 | B34: 46302 | G34: Machining | H34: A2 | I34: Training | J34: HR/HSE | K34: HC mới- 50% hiệu suất- 2 tuần-25/9 | L34: A2 ngày 7/12 - nhóm 25/9 | M34: 0.3125 | N34: 0.5 | O34: =(N34-M34)*24 -> 4.5 | P34: 1 | Q34: =P34*O34 -> 4.5
A35: ="W"&WEEKNUM(B35,21) -> W41 | B35: 46302 | G35: RC | H35: A2 | I35: Training | J35: HR/HSE | K35: HC mới- 50% hiệu suất- 2 tuần-22/9 | L35: A2 ngày 7/12 - nhóm 22/9 | M35: 0.3125 | N35: 0.5 | O35: =(N35-M35)*24 -> 4.5 | P35: 1 | Q35: =P35*O35 -> 4.5
A36: ="W"&WEEKNUM(B36,21) -> W41 | B36: 46302 | G36: RC | H36: A2 | I36: Training | J36: HR/HSE | K36: HC mới- 50% hiệu suất- 2 tuần-23/9 | L36: A2 ngày 7/12 - nhóm 23/9 | M36: 0.3125 | N36: 0.5 | O36: =(N36-M36)*24 -> 4.5 | P36: 1 | Q36: =P36*O36 -> 4.5
... A44: ="W"&WEEKNUM(B44,21) -> W41 | B44: 46302 | G44: Machining | H44: A2 | I44: Training | J44: HR/HSE | K44: HC mới- 50% hiệu suất- 2 tuần-06/10 | L44: A2 ngày 1/12 - nhóm 06/10 | M44: 0.3125 | N44: 0.5 | O44: =(N44-M44)*24 -> 4.5 | P44: 3 | Q44: =P44*O44 -> 13.5
P45: Tổng | Q45: =SUM(Q3:Q44) -> 637.5
A47: Vàng = nhân viên mới ngày đầu (P22). Xanh = nhân viên đang ghi A2 (cột Ghi chú cho biết ngày thứ mấy trong 12 ngày).

Sheet Loss time 08-10
A1: LOSS TIME WHITE WOOD - 08/10/2026
A2: Week | B2: Date (Ngày) | C2: Item's Mã hàng | D2: Code Máy Hư | E2: Q'ty | F2: Số NCR/ME | G2: Khu vực phát sinh/bộ phận hỗ trợ | H2: Code | I2: Name code | J2: Chart / bộ phận chịu trách nhiệm | K2: Lí Do | L2: Ghi chú | M2: From | N2: To | O2: LossTime (Hr) | P2: HC | Q2: Loss time labor (Hrs)
A3: ="W"&WEEKNUM(B3,21) -> W41 | B3: 46303 | G3: RC - WOOD | H3: P20 | I3: Dailly Cleaning | J3: RC WOOD | K3: Vệ sinh khu vực máy móc RC WOOD | M3: 0.29166667 | N3: 0.3125 | O3: =(N3-M3)*24 -> 0.5 | P3: 7 | Q3: =P3*O3 -> 3.5
A4: ="W"&WEEKNUM(B4,21) -> W41 | B4: 46303 | G4: RC - PANEL | H4: P20 | I4: Dailly Cleaning | J4: RC - PANEL | K4: Vệ sinh khu vực máy móc RC PANEL | M4: 0.29166667 | N4: 0.3125 | O4: =(N4-M4)*24 -> 0.5 | P4: 18 | Q4: =P4*O4 -> 9
A5: ="W"&WEEKNUM(B5,21) -> W41 | B5: 46303 | G5: Machining | H5: P20 | I5: Dailly Cleaning | J5: Machining | K5: Vệ sinh khu vực máy móc MAC FINAL | M5: 0.29166667 | N5: 0.3125 | O5: =(N5-M5)*24 -> 0.5 | P5: 7 | Q5: =P5*O5 -> 3.5
A6: ="W"&WEEKNUM(B6,21) -> W41 | B6: 46303 | G6: Machining | H6: P20 | I6: Dailly Cleaning | J6: Machining | K6: Vệ sinh khu vực máy móc PRE MAC | M6: 0.29166667 | N6: 0.3125 | O6: =(N6-M6)*24 -> 0.5 | P6: 12 | Q6: =P6*O6 -> 6
A7: ="W"&WEEKNUM(B7,21) -> W41 | B7: 46303 | G7: Assembly | H7: P20 | I7: Dailly Cleaning | J7: Assembly | K7: Quét nhà toàn xưởng khu vực ASSY | M7: 0.3125 | N7: 0.83333333 | O7: =(N7-M7)*24 -> 12.5 | P7: 2 | Q7: =P7*O7 -> 25
A8: ="W"&WEEKNUM(B8,21) -> W41 | B8: 46303 | G8: RC - PANEL | H8: P26 | I8: Recorder/ Supporter | J8: RC - PANEL | K8: Shop Floor data RC PANEL | L8: Recorder | M8: 0.3125 | N8: 0.83333333 | O8: =(N8-M8)*24 -> 12.5 | P8: 4 | Q8: =P8*O8 -> 50
A9: ="W"&WEEKNUM(B9,21) -> W41 | B9: 46303 | G9: Machining | H9: P26 | I9: Recorder/ Supporter | J9: Machining | K9: Shop Floor data- STOCK ROOM | L9: Recorder | M9: 0.3125 | N9: 0.83333333 | O9: =(N9-M9)*24 -> 12.5 | P9: 1 | Q9: =P9*O9 -> 12.5
A10: ="W"&WEEKNUM(B10,21) -> W41 | B10: 46303 | G10: Machining | H10: P26 | I10: Recorder/ Supporter | J10: Machining | K10: Shop Floor data MAC FINAL | L10: Recorder | M10: 0.3125 | N10: 0.83333333 | O10: =(N10-M10)*24 -> 12.5 | P10: 1 | Q10: =P10*O10 -> 12.5
A11: ="W"&WEEKNUM(B11,21) -> W41 | B11: 46303 | G11: RC - PANEL | H11: P26 | I11: Recorder/ Supporter | J11: RC - PANEL | K11: Theo dõi Hàng venner làm xong | L11: Recorder | M11: 0.3125 | N11: 0.83333333 | O11: =(N11-M11)*24 -> 12.5 | P11: 1 | Q11: =P11*O11 -> 12.5
A12: ="W"&WEEKNUM(B12,21) -> W41 | B12: 46303 | G12: RC - PANEL | H12: P26 | I12: Recorder/ Supporter | J12: RC - PANEL | K12: Nhận venner cho ép nóng | L12: Supporter | M12: 0.3125 | N12: 0.83333333 | O12: =(N12-M12)*24 -> 12.5 | P12: 1 | Q12: =P12*O12 -> 12.5
A13: ="W"&WEEKNUM(B13,21) -> W41 | B13: 46303 | G13: RC - WOOD | H13: P26 | I13: Recorder/ Supporter | J13: RC WOOD | K13: Lựa hàng tinh giao mac- gỗ đẹp xấu | L13: Supporter | M13: 0.3125 | N13: 0.83333333 | O13: =(N13-M13)*24 -> 12.5 | P13: 1 | Q13: =P13*O13 -> 12.5
A14: ="W"&WEEKNUM(B14,21) -> W41 | B14: 46303 | G14: RC - PANEL | H14: P26 | I14: Recorder/ Supporter | J14: RC - PANEL | K14: Ghi nhận hàng giao kho | L14: Recorder | M14: 0.3125 | N14: 0.83333333 | O14: =(N14-M14)*24 -> 12.5 | P14: 1 | Q14: =P14*O14 -> 12.5
A15: ="W"&WEEKNUM(B15,21) -> W41 | B15: 46303 | G15: RC - PANEL | H15: P26 | I15: Recorder/ Supporter | J15: RC - PANEL | K15: Kiểm hàng chất lượng vào kho | L15: Supporter | M15: 0.3125 | N15: 0.83333333 | O15: =(N15-M15)*24 -> 12.5 | P15: 1 | Q15: =P15*O15 -> 12.5
A16: ="W"&WEEKNUM(B16,21) -> W41 | B16: 46303 | G16: RC - PANEL | H16: P26 | I16: Recorder/ Supporter | J16: Machining | K16: Nhận hàng gỗ đầu vào từ RC | L16: Supporter | M16: 0.3125 | N16: 0.83333333 | O16: =(N16-M16)*24 -> 12.5 | P16: 1 | Q16: =P16*O16 -> 12.5
A17: ="W"&WEEKNUM(B17,21) -> W41 | B17: 46303 | G17: Machining | H17: P26 | I17: Recorder/ Supporter | J17: Machining | K17: Ghi nhận hàng giao kho | L17: Recorder | M17: 0.3125 | N17: 0.83333333 | O17: =(N17-M17)*24 -> 12.5 | P17: 1 | Q17: =P17*O17 -> 12.5
A18: ="W"&WEEKNUM(B18,21) -> W41 | B18: 46303 | G18: Machining | H18: P26 | I18: Recorder/ Supporter | J18: Machining | K18: quét nhà toàn xưởng khu vực ASSY | L18: Supporter | M18: 0.3125 | N18: 0.83333333 | O18: =(N18-M18)*24 -> 12.5 | P18: 1 | Q18: =P18*O18 -> 12.5
A19: ="W"&WEEKNUM(B19,21) -> W41 | B19: 46303 | G19: Machining | H19: P26 | I19: Recorder/ Supporter | J19: Machining | K19: Theo hàng pilot -hàng test-spo-subcon-NCR | L19: Recorder | M19: 0.3125 | N19: 0.83333333 | O19: =(N19-M19)*24 -> 12.5 | P19: 1 | Q19: =P19*O19 -> 12.5
... A22: ="W"&WEEKNUM(B22,21) -> W41 | B22: 46303 | G22: Assembly | H22: P26 | I22: Recorder/ Supporter | J22: Assembly | K22: Giao nhận HW- phát HW cho Line sx | L22: Supporter | M22: 0.3125 | N22: 0.83333333 | O22: =(N22-M22)*24 -> 12.5 | P22: 1 | Q22: =P22*O22 -> 12.5
A23: ="W"&WEEKNUM(B23,21) -> W41 | B23: 46303 | G23: Raw Cutting Panel | H23: P22 | I23: HR Training New Workers | J23: HR/HSE | K23: Đào tạo công nhân mới | M23: 0.33333333 | N23: 0.66666667 | O23: =(N23-M23)*24 -> 8 | P23: 1 | Q23: =P23*O23 -> 8
A24: ="W"&WEEKNUM(B24,21) -> W41 | B24: 46303 | G24: Machining | H24: P22 | I24: HR Training New Workers | J24: HR/HSE | K24: Đào tạo công nhân mới | M24: 0.33333333 | N24: 0.66666667 | O24: =(N24-M24)*24 -> 8 | P24: 3 | Q24: =P24*O24 -> 24
A25: ="W"&WEEKNUM(B25,21) -> W41 | B25: 46303 | G25: Assembly | H25: A2 | I25: Training | J25: HR/HSE | K25: HC mới- 50% hiệu suất- 2 tuần-18/9 | L25: A2 ngày 8/12 - nhóm 18/9 | M25: 0.3125 | N25: 0.5 | O25: =(N25-M25)*24 -> 4.5 | P25: 7 | Q25: =P25*O25 -> 31.5
A26: ="W"&WEEKNUM(B26,21) -> W41 | B26: 46303 | G26: Assembly | H26: A2 | I26: Training | J26: HR/HSE | K26: HC mới- 50% hiệu suất- 2 tuần-24/9 | L26: A2 ngày 8/12 - nhóm 24/9 | M26: 0.3125 | N26: 0.5 | O26: =(N26-M26)*24 -> 4.5 | P26: 5 | Q26: =P26*O26 -> 22.5
A27: ="W"&WEEKNUM(B27,21) -> W41 | B27: 46303 | G27: Assembly | H27: A2 | I27: Training | J27: HR/HSE | K27: HC mới- 50% hiệu suất- 2 tuần-25/9 | L27: A2 ngày 8/12 - nhóm 25/9 | M27: 0.3125 | N27: 0.5 | O27: =(N27-M27)*24 -> 4.5 | P27: 1 | Q27: =P27*O27 -> 4.5
A28: ="W"&WEEKNUM(B28,21) -> W41 | B28: 46303 | G28: Assembly | H28: A2 | I28: Training | J28: HR/HSE | K28: HC mới- 50% hiệu suất- 2 tuần-28/9 | L28: A2 ngày 9/12 - nhóm 28/9 | M28: 0.3125 | N28: 0.5 | O28: =(N28-M28)*24 -> 4.5 | P28: 3 | Q28: =P28*O28 -> 13.5
A29: ="W"&WEEKNUM(B29,21) -> W41 | B29: 46303 | G29: Machining | H29: A2 | I29: Training | J29: HR/HSE | K29: HC mới- 50% hiệu suất- 2 tuần-21/9 | L29: A2 ngày 8/12 - nhóm 21/9 | M29: 0.3125 | N29: 0.5 | O29: =(N29-M29)*24 -> 4.5 | P29: 2 | Q29: =P29*O29 -> 9
A30: ="W"&WEEKNUM(B30,21) -> W41 | B30: 46303 | G30: Machining | H30: A2 | I30: Training | J30: HR/HSE | K30: HC mới- 50% hiệu suất- 2 tuần-22/9 | L30: A2 ngày 8/12 - nhóm 22/9 | M30: 0.3125 | N30: 0.5 | O30: =(N30-M30)*24 -> 4.5 | P30: 4 | Q30: =P30*O30 -> 18
A31: ="W"&WEEKNUM(B31,21) -> W41 | B31: 46303 | G31: Machining | H31: A2 | I31: Training | J31: HR/HSE | K31: HC mới- 50% hiệu suất- 2 tuần-24/9 | L31: A2 ngày 8/12 - nhóm 24/9 | M31: 0.3125 | N31: 0.5 | O31: =(N31-M31)*24 -> 4.5 | P31: 3 | Q31: =P31*O31 -> 13.5
A32: ="W"&WEEKNUM(B32,21) -> W41 | B32: 46303 | G32: Machining | H32: A2 | I32: Training | J32: HR/HSE | K32: HC mới- 50% hiệu suất- 2 tuần-25/9 | L32: A2 ngày 8/12 - nhóm 25/9 | M32: 0.3125 | N32: 0.5 | O32: =(N32-M32)*24 -> 4.5 | P32: 1 | Q32: =P32*O32 -> 4.5
A33: ="W"&WEEKNUM(B33,21) -> W41 | B33: 46303 | G33: RC | H33: A2 | I33: Training | J33: HR/HSE | K33: HC mới- 50% hiệu suất- 2 tuần-22/9 | L33: A2 ngày 8/12 - nhóm 22/9 | M33: 0.3125 | N33: 0.5 | O33: =(N33-M33)*24 -> 4.5 | P33: 1 | Q33: =P33*O33 -> 4.5
A34: ="W"&WEEKNUM(B34,21) -> W41 | B34: 46303 | G34: RC | H34: A2 | I34: Training | J34: HR/HSE | K34: HC mới- 50% hiệu suất- 2 tuần-23/9 | L34: A2 ngày 8/12 - nhóm 23/9 | M34: 0.3125 | N34: 0.5 | O34: =(N34-M34)*24 -> 4.5 | P34: 1 | Q34: =P34*O34 -> 4.5
A35: ="W"&WEEKNUM(B35,21) -> W41 | B35: 46303 | G35: RC | H35: A2 | I35: Training | J35: HR/HSE | K35: HC mới- 50% hiệu suất- 2 tuần-24/9 | L35: A2 ngày 8/12 - nhóm 24/9 | M35: 0.3125 | N35: 0.5 | O35: =(N35-M35)*24 -> 4.5 | P35: 2 | Q35: =P35*O35 -> 9
A36: ="W"&WEEKNUM(B36,21) -> W41 | B36: 46303 | G36: RC | H36: A2 | I36: Training | J36: HR/HSE | K36: HC mới- 50% hiệu suất- 2 tuần-26/9 | L36: A2 ngày 8/12 - nhóm 26/9 | M36: 0.3125 | N36: 0.5 | O36: =(N36-M36)*24 -> 4.5 | P36: 1 | Q36: =P36*O36 -> 4.5
... A44: ="W"&WEEKNUM(B44,21) -> W41 | B44: 46303 | G44: Raw Cutting Panel | H44: A2 | I44: Training | J44: HR/HSE | K44: HC mới- 50% hiệu suất- 2 tuần-07/10 | L44: A2 ngày 1/12 - nhóm 07/10 | M44: 0.3125 | N44: 0.5 | O44: =(N44-M44)*24 -> 4.5 | P44: 2 | Q44: =P44*O44 -> 9
P45: Tổng | Q45: =SUM(Q3:Q44) -> 587.5
A47: Vàng = nhân viên mới ngày đầu (P22). Xanh = nhân viên đang ghi A2 (cột Ghi chú cho biết ngày thứ mấy trong 12 ngày).

Sheet Loss time 09-10
A1: LOSS TIME WHITE WOOD - 09/10/2026
A2: Week | B2: Date (Ngày) | C2: Item's Mã hàng | D2: Code Máy Hư | E2: Q'ty | F2: Số NCR/ME | G2: Khu vực phát sinh/bộ phận hỗ trợ | H2: Code | I2: Name code | J2: Chart / bộ phận chịu trách nhiệm | K2: Lí Do | L2: Ghi chú | M2: From | N2: To | O2: LossTime (Hr) | P2: HC | Q2: Loss time labor (Hrs)
A3: ="W"&WEEKNUM(B3,21) -> W41 | B3: 46304 | G3: RC - WOOD | H3: P20 | I3: Dailly Cleaning | J3: RC WOOD | K3: Vệ sinh khu vực máy móc RC WOOD | M3: 0.29166667 | N3: 0.3125 | O3: =(N3-M3)*24 -> 0.5 | P3: 7 | Q3: =P3*O3 -> 3.5
A4: ="W"&WEEKNUM(B4,21) -> W41 | B4: 46304 | G4: RC - PANEL | H4: P20 | I4: Dailly Cleaning | J4: RC - PANEL | K4: Vệ sinh khu vực máy móc RC PANEL | M4: 0.29166667 | N4: 0.3125 | O4: =(N4-M4)*24 -> 0.5 | P4: 18 | Q4: =P4*O4 -> 9
A5: ="W"&WEEKNUM(B5,21) -> W41 | B5: 46304 | G5: Machining | H5: P20 | I5: Dailly Cleaning | J5: Machining | K5: Vệ sinh khu vực máy móc MAC FINAL | M5: 0.29166667 | N5: 0.3125 | O5: =(N5-M5)*24 -> 0.5 | P5: 7 | Q5: =P5*O5 -> 3.5
A6: ="W"&WEEKNUM(B6,21) -> W41 | B6: 46304 | G6: Machining | H6: P20 | I6: Dailly Cleaning | J6: Machining | K6: Vệ sinh khu vực máy móc PRE MAC | M6: 0.29166667 | N6: 0.3125 | O6: =(N6-M6)*24 -> 0.5 | P6: 12 | Q6: =P6*O6 -> 6
A7: ="W"&WEEKNUM(B7,21) -> W41 | B7: 46304 | G7: Assembly | H7: P20 | I7: Dailly Cleaning | J7: Assembly | K7: Quét nhà toàn xưởng khu vực ASSY | M7: 0.3125 | N7: 0.83333333 | O7: =(N7-M7)*24 -> 12.5 | P7: 2 | Q7: =P7*O7 -> 25
A8: ="W"&WEEKNUM(B8,21) -> W41 | B8: 46304 | G8: RC - PANEL | H8: P26 | I8: Recorder/ Supporter | J8: RC - PANEL | K8: Shop Floor data RC PANEL | L8: Recorder | M8: 0.3125 | N8: 0.83333333 | O8: =(N8-M8)*24 -> 12.5 | P8: 4 | Q8: =P8*O8 -> 50
A9: ="W"&WEEKNUM(B9,21) -> W41 | B9: 46304 | G9: Machining | H9: P26 | I9: Recorder/ Supporter | J9: Machining | K9: Shop Floor data- STOCK ROOM | L9: Recorder | M9: 0.3125 | N9: 0.83333333 | O9: =(N9-M9)*24 -> 12.5 | P9: 1 | Q9: =P9*O9 -> 12.5
A10: ="W"&WEEKNUM(B10,21) -> W41 | B10: 46304 | G10: Machining | H10: P26 | I10: Recorder/ Supporter | J10: Machining | K10: Shop Floor data MAC FINAL | L10: Recorder | M10: 0.3125 | N10: 0.83333333 | O10: =(N10-M10)*24 -> 12.5 | P10: 1 | Q10: =P10*O10 -> 12.5
A11: ="W"&WEEKNUM(B11,21) -> W41 | B11: 46304 | G11: RC - PANEL | H11: P26 | I11: Recorder/ Supporter | J11: RC - PANEL | K11: Theo dõi Hàng venner làm xong | L11: Recorder | M11: 0.3125 | N11: 0.83333333 | O11: =(N11-M11)*24 -> 12.5 | P11: 1 | Q11: =P11*O11 -> 12.5
A12: ="W"&WEEKNUM(B12,21) -> W41 | B12: 46304 | G12: RC - PANEL | H12: P26 | I12: Recorder/ Supporter | J12: RC - PANEL | K12: Nhận venner cho ép nóng | L12: Supporter | M12: 0.3125 | N12: 0.83333333 | O12: =(N12-M12)*24 -> 12.5 | P12: 1 | Q12: =P12*O12 -> 12.5
A13: ="W"&WEEKNUM(B13,21) -> W41 | B13: 46304 | G13: RC - WOOD | H13: P26 | I13: Recorder/ Supporter | J13: RC WOOD | K13: Lựa hàng tinh giao mac- gỗ đẹp xấu | L13: Supporter | M13: 0.3125 | N13: 0.83333333 | O13: =(N13-M13)*24 -> 12.5 | P13: 1 | Q13: =P13*O13 -> 12.5
A14: ="W"&WEEKNUM(B14,21) -> W41 | B14: 46304 | G14: RC - PANEL | H14: P26 | I14: Recorder/ Supporter | J14: RC - PANEL | K14: Ghi nhận hàng giao kho | L14: Recorder | M14: 0.3125 | N14: 0.83333333 | O14: =(N14-M14)*24 -> 12.5 | P14: 1 | Q14: =P14*O14 -> 12.5
A15: ="W"&WEEKNUM(B15,21) -> W41 | B15: 46304 | G15: RC - PANEL | H15: P26 | I15: Recorder/ Supporter | J15: RC - PANEL | K15: Kiểm hàng chất lượng vào kho | L15: Supporter | M15: 0.3125 | N15: 0.83333333 | O15: =(N15-M15)*24 -> 12.5 | P15: 1 | Q15: =P15*O15 -> 12.5
A16: ="W"&WEEKNUM(B16,21) -> W41 | B16: 46304 | G16: RC - PANEL | H16: P26 | I16: Recorder/ Supporter | J16: Machining | K16: Nhận hàng gỗ đầu vào từ RC | L16: Supporter | M16: 0.3125 | N16: 0.83333333 | O16: =(N16-M16)*24 -> 12.5 | P16: 1 | Q16: =P16*O16 -> 12.5
A17: ="W"&WEEKNUM(B17,21) -> W41 | B17: 46304 | G17: Machining | H17: P26 | I17: Recorder/ Supporter | J17: Machining | K17: Ghi nhận hàng giao kho | L17: Recorder | M17: 0.3125 | N17: 0.83333333 | O17: =(N17-M17)*24 -> 12.5 | P17: 1 | Q17: =P17*O17 -> 12.5
A18: ="W"&WEEKNUM(B18,21) -> W41 | B18: 46304 | G18: Machining | H18: P26 | I18: Recorder/ Supporter | J18: Machining | K18: quét nhà toàn xưởng khu vực ASSY | L18: Supporter | M18: 0.3125 | N18: 0.83333333 | O18: =(N18-M18)*24 -> 12.5 | P18: 1 | Q18: =P18*O18 -> 12.5
A19: ="W"&WEEKNUM(B19,21) -> W41 | B19: 46304 | G19: Machining | H19: P26 | I19: Recorder/ Supporter | J19: Machining | K19: Theo hàng pilot -hàng test-spo-subcon-NCR | L19: Recorder | M19: 0.3125 | N19: 0.83333333 | O19: =(N19-M19)*24 -> 12.5 | P19: 1 | Q19: =P19*O19 -> 12.5
... A44: ="W"&WEEKNUM(B44,21) -> W41 | B44: 46304 | G44: Machining | H44: A2 | I44: Training | J44: HR/HSE | K44: HC mới- 50% hiệu suất- 2 tuần-08/10 | L44: A2 ngày 1/12 - nhóm 08/10 | M44: 0.3125 | N44: 0.5 | O44: =(N44-M44)*24 -> 4.5 | P44: 3 | Q44: =P44*O44 -> 13.5
P45: Tổng | Q45: =SUM(Q3:Q44) -> 573.5
A47: Vàng = nhân viên mới ngày đầu (P22). Xanh = nhân viên đang ghi A2 (cột Ghi chú cho biết ngày thứ mấy trong 12 ngày).

Sheet Loss time 10-10
A1: LOSS TIME WHITE WOOD - 10/10/2026
A2: Week | B2: Date (Ngày) | C2: Item's Mã hàng | D2: Code Máy Hư | E2: Q'ty | F2: Số NCR/ME | G2: Khu vực phát sinh/bộ phận hỗ trợ | H2: Code | I2: Name code | J2: Chart / bộ phận chịu trách nhiệm | K2: Lí Do | L2: Ghi chú | M2: From | N2: To | O2: LossTime (Hr) | P2: HC | Q2: Loss time labor (Hrs)
A3: ="W"&WEEKNUM(B3,21) -> W41 | B3: 46305 | G3: RC - WOOD | H3: P20 | I3: Dailly Cleaning | J3: RC WOOD | K3: Vệ sinh khu vực máy móc RC WOOD | M3: 0.29166667 | N3: 0.3125 | O3: =(N3-M3)*24 -> 0.5 | P3: 7 | Q3: =P3*O3 -> 3.5
A4: ="W"&WEEKNUM(B4,21) -> W41 | B4: 46305 | G4: RC - PANEL | H4: P20 | I4: Dailly Cleaning | J4: RC - PANEL | K4: Vệ sinh khu vực máy móc RC PANEL | M4: 0.29166667 | N4: 0.3125 | O4: =(N4-M4)*24 -> 0.5 | P4: 18 | Q4: =P4*O4 -> 9
A5: ="W"&WEEKNUM(B5,21) -> W41 | B5: 46305 | G5: Machining | H5: P20 | I5: Dailly Cleaning | J5: Machining | K5: Vệ sinh khu vực máy móc MAC FINAL | M5: 0.29166667 | N5: 0.3125 | O5: =(N5-M5)*24 -> 0.5 | P5: 7 | Q5: =P5*O5 -> 3.5
A6: ="W"&WEEKNUM(B6,21) -> W41 | B6: 46305 | G6: Machining | H6: P20 | I6: Dailly Cleaning | J6: Machining | K6: Vệ sinh khu vực máy móc PRE MAC | M6: 0.29166667 | N6: 0.3125 | O6: =(N6-M6)*24 -> 0.5 | P6: 12 | Q6: =P6*O6 -> 6
A7: ="W"&WEEKNUM(B7,21) -> W41 | B7: 46305 | G7: Assembly | H7: P20 | I7: Dailly Cleaning | J7: Assembly | K7: Quét nhà toàn xưởng khu vực ASSY | M7: 0.3125 | N7: 0.64583333 | O7: =(N7-M7)*24 -> 8 | P7: 2 | Q7: =P7*O7 -> 16
A8: ="W"&WEEKNUM(B8,21) -> W41 | B8: 46305 | G8: RC - PANEL | H8: P26 | I8: Recorder/ Supporter | J8: RC - PANEL | K8: Shop Floor data RC PANEL | L8: Recorder | M8: 0.3125 | N8: 0.64583333 | O8: =(N8-M8)*24 -> 8 | P8: 4 | Q8: =P8*O8 -> 32
A9: ="W"&WEEKNUM(B9,21) -> W41 | B9: 46305 | G9: Machining | H9: P26 | I9: Recorder/ Supporter | J9: Machining | K9: Shop Floor data- STOCK ROOM | L9: Recorder | M9: 0.3125 | N9: 0.64583333 | O9: =(N9-M9)*24 -> 8 | P9: 1 | Q9: =P9*O9 -> 8
A10: ="W"&WEEKNUM(B10,21) -> W41 | B10: 46305 | G10: Machining | H10: P26 | I10: Recorder/ Supporter | J10: Machining | K10: Shop Floor data MAC FINAL | L10: Recorder | M10: 0.3125 | N10: 0.64583333 | O10: =(N10-M10)*24 -> 8 | P10: 1 | Q10: =P10*O10 -> 8
A11: ="W"&WEEKNUM(B11,21) -> W41 | B11: 46305 | G11: RC - PANEL | H11: P26 | I11: Recorder/ Supporter | J11: RC - PANEL | K11: Theo dõi Hàng venner làm xong | L11: Recorder | M11: 0.3125 | N11: 0.64583333 | O11: =(N11-M11)*24 -> 8 | P11: 1 | Q11: =P11*O11 -> 8
A12: ="W"&WEEKNUM(B12,21) -> W41 | B12: 46305 | G12: RC - PANEL | H12: P26 | I12: Recorder/ Supporter | J12: RC - PANEL | K12: Nhận venner cho ép nóng | L12: Supporter | M12: 0.3125 | N12: 0.64583333 | O12: =(N12-M12)*24 -> 8 | P12: 1 | Q12: =P12*O12 -> 8
A13: ="W"&WEEKNUM(B13,21) -> W41 | B13: 46305 | G13: RC - WOOD | H13: P26 | I13: Recorder/ Supporter | J13: RC WOOD | K13: Lựa hàng tinh giao mac- gỗ đẹp xấu | L13: Supporter | M13: 0.3125 | N13: 0.64583333 | O13: =(N13-M13)*24 -> 8 | P13: 1 | Q13: =P13*O13 -> 8
A14: ="W"&WEEKNUM(B14,21) -> W41 | B14: 46305 | G14: RC - PANEL | H14: P26 | I14: Recorder/ Supporter | J14: RC - PANEL | K14: Ghi nhận hàng giao kho | L14: Recorder | M14: 0.3125 | N14: 0.64583333 | O14: =(N14-M14)*24 -> 8 | P14: 1 | Q14: =P14*O14 -> 8
A15: ="W"&WEEKNUM(B15,21) -> W41 | B15: 46305 | G15: RC - PANEL | H15: P26 | I15: Recorder/ Supporter | J15: RC - PANEL | K15: Kiểm hàng chất lượng vào kho | L15: Supporter | M15: 0.3125 | N15: 0.64583333 | O15: =(N15-M15)*24 -> 8 | P15: 1 | Q15: =P15*O15 -> 8
A16: ="W"&WEEKNUM(B16,21) -> W41 | B16: 46305 | G16: RC - PANEL | H16: P26 | I16: Recorder/ Supporter | J16: Machining | K16: Nhận hàng gỗ đầu vào từ RC | L16: Supporter | M16: 0.3125 | N16: 0.64583333 | O16: =(N16-M16)*24 -> 8 | P16: 1 | Q16: =P16*O16 -> 8
A17: ="W"&WEEKNUM(B17,21) -> W41 | B17: 46305 | G17: Machining | H17: P26 | I17: Recorder/ Supporter | J17: Machining | K17: Ghi nhận hàng giao kho | L17: Recorder | M17: 0.3125 | N17: 0.64583333 | O17: =(N17-M17)*24 -> 8 | P17: 1 | Q17: =P17*O17 -> 8
A18: ="W"&WEEKNUM(B18,21) -> W41 | B18: 46305 | G18: Machining | H18: P26 | I18: Recorder/ Supporter | J18: Machining | K18: quét nhà toàn xưởng khu vực ASSY | L18: Supporter | M18: 0.3125 | N18: 0.64583333 | O18: =(N18-M18)*24 -> 8 | P18: 1 | Q18: =P18*O18 -> 8
A19: ="W"&WEEKNUM(B19,21) -> W41 | B19: 46305 | G19: Machining | H19: P26 | I19: Recorder/ Supporter | J19: Machining | K19: Theo hàng pilot -hàng test-spo-subcon-NCR | L19: Recorder | M19: 0.3125 | N19: 0.64583333 | O19: =(N19-M19)*24 -> 8 | P19: 1 | Q19: =P19*O19 -> 8
... A44: ="W"&WEEKNUM(B44,21) -> W41 | B44: 46305 | G44: Machining | H44: A2 | I44: Training | J44: HR/HSE | K44: HC mới- 50% hiệu suất- 2 tuần-08/10 | L44: A2 ngày 2/12 - nhóm 08/10 | M44: 0.3125 | N44: 0.5 | O44: =(N44-M44)*24 -> 4.5 | P44: 3 | Q44: =P44*O44 -> 13.5
P45: Tổng | Q45: =SUM(Q3:Q44) -> 483.5
A47: Vàng = nhân viên mới ngày đầu (P22). Xanh = nhân viên đang ghi A2 (cột Ghi chú cho biết ngày thứ mấy trong 12 ngày).

Sheet Loss time 12-10
A1: LOSS TIME WHITE WOOD - 12/10/2026
A2: Week | B2: Date (Ngày) | C2: Item's Mã hàng | D2: Code Máy Hư | E2: Q'ty | F2: Số NCR/ME | G2: Khu vực phát sinh/bộ phận hỗ trợ | H2: Code | I2: Name code | J2: Chart / bộ phận chịu trách nhiệm | K2: Lí Do | L2: Ghi chú | M2: From | N2: To | O2: LossTime (Hr) | P2: HC | Q2: Loss time labor (Hrs)
A3: ="W"&WEEKNUM(B3,21) -> W42 | B3: 46307 | G3: RC - WOOD | H3: P20 | I3: Dailly Cleaning | J3: RC WOOD | K3: Vệ sinh khu vực máy móc RC WOOD | M3: 0.29166667 | N3: 0.3125 | O3: =(N3-M3)*24 -> 0.5 | P3: 7 | Q3: =P3*O3 -> 3.5
A4: ="W"&WEEKNUM(B4,21) -> W42 | B4: 46307 | G4: RC - PANEL | H4: P20 | I4: Dailly Cleaning | J4: RC - PANEL | K4: Vệ sinh khu vực máy móc RC PANEL | M4: 0.29166667 | N4: 0.3125 | O4: =(N4-M4)*24 -> 0.5 | P4: 18 | Q4: =P4*O4 -> 9
A5: ="W"&WEEKNUM(B5,21) -> W42 | B5: 46307 | G5: Machining | H5: P20 | I5: Dailly Cleaning | J5: Machining | K5: Vệ sinh khu vực máy móc MAC FINAL | M5: 0.29166667 | N5: 0.3125 | O5: =(N5-M5)*24 -> 0.5 | P5: 7 | Q5: =P5*O5 -> 3.5
A6: ="W"&WEEKNUM(B6,21) -> W42 | B6: 46307 | G6: Machining | H6: P20 | I6: Dailly Cleaning | J6: Machining | K6: Vệ sinh khu vực máy móc PRE MAC | M6: 0.29166667 | N6: 0.3125 | O6: =(N6-M6)*24 -> 0.5 | P6: 12 | Q6: =P6*O6 -> 6
A7: ="W"&WEEKNUM(B7,21) -> W42 | B7: 46307 | G7: Assembly | H7: P20 | I7: Dailly Cleaning | J7: Assembly | K7: Quét nhà toàn xưởng khu vực ASSY | M7: 0.3125 | N7: 0.83333333 | O7: =(N7-M7)*24 -> 12.5 | P7: 2 | Q7: =P7*O7 -> 25
A8: ="W"&WEEKNUM(B8,21) -> W42 | B8: 46307 | G8: RC - PANEL | H8: P26 | I8: Recorder/ Supporter | J8: RC - PANEL | K8: Shop Floor data RC PANEL | L8: Recorder | M8: 0.3125 | N8: 0.83333333 | O8: =(N8-M8)*24 -> 12.5 | P8: 4 | Q8: =P8*O8 -> 50
A9: ="W"&WEEKNUM(B9,21) -> W42 | B9: 46307 | G9: Machining | H9: P26 | I9: Recorder/ Supporter | J9: Machining | K9: Shop Floor data- STOCK ROOM | L9: Recorder | M9: 0.3125 | N9: 0.83333333 | O9: =(N9-M9)*24 -> 12.5 | P9: 1 | Q9: =P9*O9 -> 12.5
A10: ="W"&WEEKNUM(B10,21) -> W42 | B10: 46307 | G10: Machining | H10: P26 | I10: Recorder/ Supporter | J10: Machining | K10: Shop Floor data MAC FINAL | L10: Recorder | M10: 0.3125 | N10: 0.83333333 | O10: =(N10-M10)*24 -> 12.5 | P10: 1 | Q10: =P10*O10 -> 12.5
A11: ="W"&WEEKNUM(B11,21) -> W42 | B11: 46307 | G11: RC - PANEL | H11: P26 | I11: Recorder/ Supporter | J11: RC - PANEL | K11: Theo dõi Hàng venner làm xong | L11: Recorder | M11: 0.3125 | N11: 0.83333333 | O11: =(N11-M11)*24 -> 12.5 | P11: 1 | Q11: =P11*O11 -> 12.5
A12: ="W"&WEEKNUM(B12,21) -> W42 | B12: 46307 | G12: RC - PANEL | H12: P26 | I12: Recorder/ Supporter | J12: RC - PANEL | K12: Nhận venner cho ép nóng | L12: Supporter | M12: 0.3125 | N12: 0.83333333 | O12: =(N12-M12)*24 -> 12.5 | P12: 1 | Q12: =P12*O12 -> 12.5
A13: ="W"&WEEKNUM(B13,21) -> W42 | B13: 46307 | G13: RC - WOOD | H13: P26 | I13: Recorder/ Supporter | J13: RC WOOD | K13: Lựa hàng tinh giao mac- gỗ đẹp xấu | L13: Supporter | M13: 0.3125 | N13: 0.83333333 | O13: =(N13-M13)*24 -> 12.5 | P13: 1 | Q13: =P13*O13 -> 12.5
A14: ="W"&WEEKNUM(B14,21) -> W42 | B14: 46307 | G14: RC - PANEL | H14: P26 | I14: Recorder/ Supporter | J14: RC - PANEL | K14: Ghi nhận hàng giao kho | L14: Recorder | M14: 0.3125 | N14: 0.83333333 | O14: =(N14-M14)*24 -> 12.5 | P14: 1 | Q14: =P14*O14 -> 12.5
A15: ="W"&WEEKNUM(B15,21) -> W42 | B15: 46307 | G15: RC - PANEL | H15: P26 | I15: Recorder/ Supporter | J15: RC - PANEL | K15: Kiểm hàng chất lượng vào kho | L15: Supporter | M15: 0.3125 | N15: 0.83333333 | O15: =(N15-M15)*24 -> 12.5 | P15: 1 | Q15: =P15*O15 -> 12.5
A16: ="W"&WEEKNUM(B16,21) -> W42 | B16: 46307 | G16: RC - PANEL | H16: P26 | I16: Recorder/ Supporter | J16: Machining | K16: Nhận hàng gỗ đầu vào từ RC | L16: Supporter | M16: 0.3125 | N16: 0.83333333 | O16: =(N16-M16)*24 -> 12.5 | P16: 1 | Q16: =P16*O16 -> 12.5
A17: ="W"&WEEKNUM(B17,21) -> W42 | B17: 46307 | G17: Machining | H17: P26 | I17: Recorder/ Supporter | J17: Machining | K17: Ghi nhận hàng giao kho | L17: Recorder | M17: 0.3125 | N17: 0.83333333 | O17: =(N17-M17)*24 -> 12.5 | P17: 1 | Q17: =P17*O17 -> 12.5
A18: ="W"&WEEKNUM(B18,21) -> W42 | B18: 46307 | G18: Machining | H18: P26 | I18: Recorder/ Supporter | J18: Machining | K18: quét nhà toàn xưởng khu vực ASSY | L18: Supporter | M18: 0.3125 | N18: 0.83333333 | O18: =(N18-M18)*24 -> 12.5 | P18: 1 | Q18: =P18*O18 -> 12.5
A19: ="W"&WEEKNUM(B19,21) -> W42 | B19: 46307 | G19: Machining | H19: P26 | I19: Recorder/ Supporter | J19: Machining | K19: Theo hàng pilot -hàng test-spo-subcon-NCR | L19: Recorder | M19: 0.3125 | N19: 0.83333333 | O19: =(N19-M19)*24 -> 12.5 | P19: 1 | Q19: =P19*O19 -> 12.5
... A22: ="W"&WEEKNUM(B22,21) -> W42 | B22: 46307 | G22: Assembly | H22: P26 | I22: Recorder/ Supporter | J22: Assembly | K22: Giao nhận HW- phát HW cho Line sx | L22: Supporter | M22: 0.3125 | N22: 0.83333333 | O22: =(N22-M22)*24 -> 12.5 | P22: 1 | Q22: =P22*O22 -> 12.5
A23: ="W"&WEEKNUM(B23,21) -> W42 | B23: 46307 | G23: Assembly | H23: P22 | I23: HR Training New Workers | J23: HR/HSE | K23: Đào tạo công nhân mới | M23: 0.33333333 | N23: 0.66666667 | O23: =(N23-M23)*24 -> 8 | P23: 2 | Q23: =P23*O23 -> 16
A24: ="W"&WEEKNUM(B24,21) -> W42 | B24: 46307 | G24: Raw Cutting Panel | H24: P22 | I24: HR Training New Workers | J24: HR/HSE | K24: Đào tạo công nhân mới | M24: 0.33333333 | N24: 0.66666667 | O24: =(N24-M24)*24 -> 8 | P24: 1 | Q24: =P24*O24 -> 8
A25: ="W"&WEEKNUM(B25,21) -> W42 | B25: 46307 | G25: Assembly | H25: A2 | I25: Training | J25: HR/HSE | K25: HC mới- 50% hiệu suất- 2 tuần-18/9 | L25: A2 ngày 11/12 - nhóm 18/9 | M25: 0.3125 | N25: 0.5 | O25: =(N25-M25)*24 -> 4.5 | P25: 7 | Q25: =P25*O25 -> 31.5
A26: ="W"&WEEKNUM(B26,21) -> W42 | B26: 46307 | G26: Assembly | H26: A2 | I26: Training | J26: HR/HSE | K26: HC mới- 50% hiệu suất- 2 tuần-24/9 | L26: A2 ngày 11/12 - nhóm 24/9 | M26: 0.3125 | N26: 0.5 | O26: =(N26-M26)*24 -> 4.5 | P26: 5 | Q26: =P26*O26 -> 22.5
A27: ="W"&WEEKNUM(B27,21) -> W42 | B27: 46307 | G27: Assembly | H27: A2 | I27: Training | J27: HR/HSE | K27: HC mới- 50% hiệu suất- 2 tuần-25/9 | L27: A2 ngày 11/12 - nhóm 25/9 | M27: 0.3125 | N27: 0.5 | O27: =(N27-M27)*24 -> 4.5 | P27: 1 | Q27: =P27*O27 -> 4.5
A28: ="W"&WEEKNUM(B28,21) -> W42 | B28: 46307 | G28: Assembly | H28: A2 | I28: Training | J28: HR/HSE | K28: HC mới- 50% hiệu suất- 2 tuần-28/9 | L28: A2 ngày 12/12 - nhóm 28/9 | M28: 0.3125 | N28: 0.5 | O28: =(N28-M28)*24 -> 4.5 | P28: 3 | Q28: =P28*O28 -> 13.5
A29: ="W"&WEEKNUM(B29,21) -> W42 | B29: 46307 | G29: Machining | H29: A2 | I29: Training | J29: HR/HSE | K29: HC mới- 50% hiệu suất- 2 tuần-21/9 | L29: A2 ngày 11/12 - nhóm 21/9 | M29: 0.3125 | N29: 0.5 | O29: =(N29-M29)*24 -> 4.5 | P29: 2 | Q29: =P29*O29 -> 9
A30: ="W"&WEEKNUM(B30,21) -> W42 | B30: 46307 | G30: Machining | H30: A2 | I30: Training | J30: HR/HSE | K30: HC mới- 50% hiệu suất- 2 tuần-22/9 | L30: A2 ngày 11/12 - nhóm 22/9 | M30: 0.3125 | N30: 0.5 | O30: =(N30-M30)*24 -> 4.5 | P30: 4 | Q30: =P30*O30 -> 18
A31: ="W"&WEEKNUM(B31,21) -> W42 | B31: 46307 | G31: Machining | H31: A2 | I31: Training | J31: HR/HSE | K31: HC mới- 50% hiệu suất- 2 tuần-24/9 | L31: A2 ngày 11/12 - nhóm 24/9 | M31: 0.3125 | N31: 0.5 | O31: =(N31-M31)*24 -> 4.5 | P31: 3 | Q31: =P31*O31 -> 13.5
A32: ="W"&WEEKNUM(B32,21) -> W42 | B32: 46307 | G32: Machining | H32: A2 | I32: Training | J32: HR/HSE | K32: HC mới- 50% hiệu suất- 2 tuần-25/9 | L32: A2 ngày 11/12 - nhóm 25/9 | M32: 0.3125 | N32: 0.5 | O32: =(N32-M32)*24 -> 4.5 | P32: 1 | Q32: =P32*O32 -> 4.5
A33: ="W"&WEEKNUM(B33,21) -> W42 | B33: 46307 | G33: RC | H33: A2 | I33: Training | J33: HR/HSE | K33: HC mới- 50% hiệu suất- 2 tuần-22/9 | L33: A2 ngày 11/12 - nhóm 22/9 | M33: 0.3125 | N33: 0.5 | O33: =(N33-M33)*24 -> 4.5 | P33: 1 | Q33: =P33*O33 -> 4.5
A34: ="W"&WEEKNUM(B34,21) -> W42 | B34: 46307 | G34: RC | H34: A2 | I34: Training | J34: HR/HSE | K34: HC mới- 50% hiệu suất- 2 tuần-23/9 | L34: A2 ngày 11/12 - nhóm 23/9 | M34: 0.3125 | N34: 0.5 | O34: =(N34-M34)*24 -> 4.5 | P34: 1 | Q34: =P34*O34 -> 4.5
A35: ="W"&WEEKNUM(B35,21) -> W42 | B35: 46307 | G35: RC | H35: A2 | I35: Training | J35: HR/HSE | K35: HC mới- 50% hiệu suất- 2 tuần-24/9 | L35: A2 ngày 11/12 - nhóm 24/9 | M35: 0.3125 | N35: 0.5 | O35: =(N35-M35)*24 -> 4.5 | P35: 2 | Q35: =P35*O35 -> 9
A36: ="W"&WEEKNUM(B36,21) -> W42 | B36: 46307 | G36: RC | H36: A2 | I36: Training | J36: HR/HSE | K36: HC mới- 50% hiệu suất- 2 tuần-26/9 | L36: A2 ngày 11/12 - nhóm 26/9 | M36: 0.3125 | N36: 0.5 | O36: =(N36-M36)*24 -> 4.5 | P36: 1 | Q36: =P36*O36 -> 4.5
... A46: ="W"&WEEKNUM(B46,21) -> W42 | B46: 46307 | G46: Machining | H46: A2 | I46: Training | J46: HR/HSE | K46: HC mới- 50% hiệu suất- 2 tuần-08/10 | L46: A2 ngày 3/12 - nhóm 08/10 | M46: 0.3125 | N46: 0.5 | O46: =(N46-M46)*24 -> 4.5 | P46: 3 | Q46: =P46*O46 -> 13.5
P47: Tổng | Q47: =SUM(Q3:Q46) -> 597.5
A49: Vàng = nhân viên mới ngày đầu (P22). Xanh = nhân viên đang ghi A2 (cột Ghi chú cho biết ngày thứ mấy trong 12 ngày).

Sheet Loss time 13-10
A1: LOSS TIME WHITE WOOD - 13/10/2026
A2: Week | B2: Date (Ngày) | C2: Item's Mã hàng | D2: Code Máy Hư | E2: Q'ty | F2: Số NCR/ME | G2: Khu vực phát sinh/bộ phận hỗ trợ | H2: Code | I2: Name code | J2: Chart / bộ phận chịu trách nhiệm | K2: Lí Do | L2: Ghi chú | M2: From | N2: To | O2: LossTime (Hr) | P2: HC | Q2: Loss time labor (Hrs)
A3: ="W"&WEEKNUM(B3,21) -> W42 | B3: 46308 | G3: RC - WOOD | H3: P20 | I3: Dailly Cleaning | J3: RC WOOD | K3: Vệ sinh khu vực máy móc RC WOOD | M3: 0.29166667 | N3: 0.3125 | O3: =(N3-M3)*24 -> 0.5 | P3: 7 | Q3: =P3*O3 -> 3.5
A4: ="W"&WEEKNUM(B4,21) -> W42 | B4: 46308 | G4: RC - PANEL | H4: P20 | I4: Dailly Cleaning | J4: RC - PANEL | K4: Vệ sinh khu vực máy móc RC PANEL | M4: 0.29166667 | N4: 0.3125 | O4: =(N4-M4)*24 -> 0.5 | P4: 18 | Q4: =P4*O4 -> 9
A5: ="W"&WEEKNUM(B5,21) -> W42 | B5: 46308 | G5: Machining | H5: P20 | I5: Dailly Cleaning | J5: Machining | K5: Vệ sinh khu vực máy móc MAC FINAL | M5: 0.29166667 | N5: 0.3125 | O5: =(N5-M5)*24 -> 0.5 | P5: 7 | Q5: =P5*O5 -> 3.5
A6: ="W"&WEEKNUM(B6,21) -> W42 | B6: 46308 | G6: Machining | H6: P20 | I6: Dailly Cleaning | J6: Machining | K6: Vệ sinh khu vực máy móc PRE MAC | M6: 0.29166667 | N6: 0.3125 | O6: =(N6-M6)*24 -> 0.5 | P6: 12 | Q6: =P6*O6 -> 6
A7: ="W"&WEEKNUM(B7,21) -> W42 | B7: 46308 | G7: Assembly | H7: P20 | I7: Dailly Cleaning | J7: Assembly | K7: Quét nhà toàn xưởng khu vực ASSY | M7: 0.3125 | N7: 0.83333333 | O7: =(N7-M7)*24 -> 12.5 | P7: 2 | Q7: =P7*O7 -> 25
A8: ="W"&WEEKNUM(B8,21) -> W42 | B8: 46308 | G8: RC - PANEL | H8: P26 | I8: Recorder/ Supporter | J8: RC - PANEL | K8: Shop Floor data RC PANEL | L8: Recorder | M8: 0.3125 | N8: 0.83333333 | O8: =(N8-M8)*24 -> 12.5 | P8: 4 | Q8: =P8*O8 -> 50
A9: ="W"&WEEKNUM(B9,21) -> W42 | B9: 46308 | G9: Machining | H9: P26 | I9: Recorder/ Supporter | J9: Machining | K9: Shop Floor data- STOCK ROOM | L9: Recorder | M9: 0.3125 | N9: 0.83333333 | O9: =(N9-M9)*24 -> 12.5 | P9: 1 | Q9: =P9*O9 -> 12.5
A10: ="W"&WEEKNUM(B10,21) -> W42 | B10: 46308 | G10: Machining | H10: P26 | I10: Recorder/ Supporter | J10: Machining | K10: Shop Floor data MAC FINAL | L10: Recorder | M10: 0.3125 | N10: 0.83333333 | O10: =(N10-M10)*24 -> 12.5 | P10: 1 | Q10: =P10*O10 -> 12.5
A11: ="W"&WEEKNUM(B11,21) -> W42 | B11: 46308 | G11: RC - PANEL | H11: P26 | I11: Recorder/ Supporter | J11: RC - PANEL | K11: Theo dõi Hàng venner làm xong | L11: Recorder | M11: 0.3125 | N11: 0.83333333 | O11: =(N11-M11)*24 -> 12.5 | P11: 1 | Q11: =P11*O11 -> 12.5
A12: ="W"&WEEKNUM(B12,21) -> W42 | B12: 46308 | G12: RC - PANEL | H12: P26 | I12: Recorder/ Supporter | J12: RC - PANEL | K12: Nhận venner cho ép nóng | L12: Supporter | M12: 0.3125 | N12: 0.83333333 | O12: =(N12-M12)*24 -> 12.5 | P12: 1 | Q12: =P12*O12 -> 12.5
A13: ="W"&WEEKNUM(B13,21) -> W42 | B13: 46308 | G13: RC - WOOD | H13: P26 | I13: Recorder/ Supporter | J13: RC WOOD | K13: Lựa hàng tinh giao mac- gỗ đẹp xấu | L13: Supporter | M13: 0.3125 | N13: 0.83333333 | O13: =(N13-M13)*24 -> 12.5 | P13: 1 | Q13: =P13*O13 -> 12.5
A14: ="W"&WEEKNUM(B14,21) -> W42 | B14: 46308 | G14: RC - PANEL | H14: P26 | I14: Recorder/ Supporter | J14: RC - PANEL | K14: Ghi nhận hàng giao kho | L14: Recorder | M14: 0.3125 | N14: 0.83333333 | O14: =(N14-M14)*24 -> 12.5 | P14: 1 | Q14: =P14*O14 -> 12.5
A15: ="W"&WEEKNUM(B15,21) -> W42 | B15: 46308 | G15: RC - PANEL | H15: P26 | I15: Recorder/ Supporter | J15: RC - PANEL | K15: Kiểm hàng chất lượng vào kho | L15: Supporter | M15: 0.3125 | N15: 0.83333333 | O15: =(N15-M15)*24 -> 12.5 | P15: 1 | Q15: =P15*O15 -> 12.5
A16: ="W"&WEEKNUM(B16,21) -> W42 | B16: 46308 | G16: RC - PANEL | H16: P26 | I16: Recorder/ Supporter | J16: Machining | K16: Nhận hàng gỗ đầu vào từ RC | L16: Supporter | M16: 0.3125 | N16: 0.83333333 | O16: =(N16-M16)*24 -> 12.5 | P16: 1 | Q16: =P16*O16 -> 12.5
A17: ="W"&WEEKNUM(B17,21) -> W42 | B17: 46308 | G17: Machining | H17: P26 | I17: Recorder/ Supporter | J17: Machining | K17: Ghi nhận hàng giao kho | L17: Recorder | M17: 0.3125 | N17: 0.83333333 | O17: =(N17-M17)*24 -> 12.5 | P17: 1 | Q17: =P17*O17 -> 12.5
A18: ="W"&WEEKNUM(B18,21) -> W42 | B18: 46308 | G18: Machining | H18: P26 | I18: Recorder/ Supporter | J18: Machining | K18: quét nhà toàn xưởng khu vực ASSY | L18: Supporter | M18: 0.3125 | N18: 0.83333333 | O18: =(N18-M18)*24 -> 12.5 | P18: 1 | Q18: =P18*O18 -> 12.5
A19: ="W"&WEEKNUM(B19,21) -> W42 | B19: 46308 | G19: Machining | H19: P26 | I19: Recorder/ Supporter | J19: Machining | K19: Theo hàng pilot -hàng test-spo-subcon-NCR | L19: Recorder | M19: 0.3125 | N19: 0.83333333 | O19: =(N19-M19)*24 -> 12.5 | P19: 1 | Q19: =P19*O19 -> 12.5
... A22: ="W"&WEEKNUM(B22,21) -> W42 | B22: 46308 | G22: Assembly | H22: P26 | I22: Recorder/ Supporter | J22: Assembly | K22: Giao nhận HW- phát HW cho Line sx | L22: Supporter | M22: 0.3125 | N22: 0.83333333 | O22: =(N22-M22)*24 -> 12.5 | P22: 1 | Q22: =P22*O22 -> 12.5
