Workbook

Sheet S32 5-10 đến 29-10
A1: LOSS TIME MÃ S32 (OTHER SUPPORT OF PRODUCTION) - 05/10 ĐẾN 29/10/2026 - LÀM RIÊNG, KHÔNG LẪN MÃ KHÁC
A2: Week | B2: Date (Ngày) | C2: Item's Mã hàng | D2: Code Máy Hư | E2: Q'ty | F2: Số NCR/ME | G2: Khu vực phát sinh/bộ phận hỗ trợ | H2: Code | I2: Name code | J2: Chart / bộ phận chịu trách nhiệm | K2: Lí Do | L2: Ghi chú | M2: From | N2: To | O2: LossTime (Hr) | P2: HC | Q2: Loss time labor (Hrs) | R2: Nguồn
A3: ="W"&WEEKNUM(B3,21) -> W41 | B3: 46300 | C3: CZ842F188+CZ842F381+CZ842F409 | E3: 25 | G3: Raw Cutting | H3: S32 | I3: Other Support of Production | J3: OTHERS (INVESTIGATE) | K3: Hỗ trợ P1 ép nóng | L3: Hỗ trợ P1 (3 mã hàng, 1 ca) | M3: 0.27083333 | N3: 0.4375 | O3: =(N3-M3)*24 -> 4 | P3: 4 | Q3: =P3*O3 -> 16 | R3: File Ép nóng
A4: ="W"&WEEKNUM(B4,21) -> W41 | B4: 46300 | C4: CE517F992-TOP+CE592F1222-TOP | E4: 50 | G4: Raw Cutting | H4: S32 | I4: Other Support of Production | J4: OTHERS (INVESTIGATE) | K4: Hỗ trợ P1 ép nóng - ép lót | L4: Ép lót (2 mã hàng) | M4: 0.29166667 | N4: 0.54166667 | O4: =(N4-M4)*24 -> 6 | P4: 5 | Q4: =P4*O4 -> 30 | R4: File Ép nóng
A5: ="W"&WEEKNUM(B5,21) -> W41 | B5: 46300 | G5: Raw Cutting | H5: S32 | I5: Other Support of Production | J5: FINISHING | K5: Không có bomtime chuyền UV | L5: HC làm việc (ca thường) | M5: 0.3125 | N5: 0.64583333 | O5: =(N5-M5)*24 -> 8 | P5: 11 | Q5: =P5*O5 -> 88 | R5: File UV (báo cáo ngày)
A6: ="W"&WEEKNUM(B6,21) -> W41 | B6: 46300 | G6: Raw Cutting | H6: S32 | I6: Other Support of Production | J6: FINISHING | K6: Không có bomtime chuyền UV | L6: HC tăng ca (OT 4 giờ) | M6: 0.64583333 | N6: 0.8125 | O6: =(N6-M6)*24 -> 4 | P6: 8 | Q6: =P6*O6 -> 32 | R6: File UV (báo cáo ngày)
A7: ="W"&WEEKNUM(B7,21) -> W41 | B7: 46301 | C7: CE517F992-TOP+CE592F1222-TOP | E7: 50 | G7: Raw Cutting | H7: S32 | I7: Other Support of Production | J7: OTHERS (INVESTIGATE) | K7: Hỗ trợ P1 ép nóng - ép chính | L7: Ép chính (2 mã hàng) | M7: 0.29166667 | N7: 0.75 | O7: =(N7-M7)*24 -> 11 | P7: 5 | Q7: =P7*O7 -> 55 | R7: File Ép nóng
A8: ="W"&WEEKNUM(B8,21) -> W41 | B8: 46301 | G8: Raw Cutting | H8: S32 | I8: Other Support of Production | J8: FINISHING | K8: Không có bomtime chuyền UV | L8: HC làm việc (ca thường) | M8: 0.3125 | N8: 0.64583333 | O8: =(N8-M8)*24 -> 8 | P8: 11 | Q8: =P8*O8 -> 88 | R8: File UV (báo cáo ngày)
A9: ="W"&WEEKNUM(B9,21) -> W41 | B9: 46301 | G9: Raw Cutting | H9: S32 | I9: Other Support of Production | J9: FINISHING | K9: Không có bomtime chuyền UV | L9: HC tăng ca (OT 4 giờ) | M9: 0.64583333 | N9: 0.8125 | O9: =(N9-M9)*24 -> 4 | P9: 8 | Q9: =P9*O9 -> 32 | R9: File UV (báo cáo ngày)
A10: ="W"&WEEKNUM(B10,21) -> W41 | B10: 46302 | G10: Raw Cutting | H10: S32 | I10: Other Support of Production | J10: FINISHING | K10: Không có bomtime chuyền UV | L10: HC làm việc (ca thường) | M10: 0.3125 | N10: 0.64583333 | O10: =(N10-M10)*24 -> 8 | P10: 10 | Q10: =P10*O10 -> 80 | R10: File UV (báo cáo ngày)
A11: ="W"&WEEKNUM(B11,21) -> W41 | B11: 46302 | G11: Raw Cutting | H11: S32 | I11: Other Support of Production | J11: FINISHING | K11: Không có bomtime chuyền UV | L11: HC tăng ca (OT 4 giờ) | M11: 0.64583333 | N11: 0.8125 | O11: =(N11-M11)*24 -> 4 | P11: 8 | Q11: =P11*O11 -> 32 | R11: File UV (báo cáo ngày)
A12: ="W"&WEEKNUM(B12,21) -> W41 | B12: 46303 | G12: Raw Cutting | H12: S32 | I12: Other Support of Production | J12: FINISHING | K12: Không có bomtime chuyền UV | L12: HC làm việc (ca thường) | M12: 0.3125 | N12: 0.64583333 | O12: =(N12-M12)*24 -> 8 | P12: 10 | Q12: =P12*O12 -> 80 | R12: File UV (báo cáo ngày)
A13: ="W"&WEEKNUM(B13,21) -> W41 | B13: 46303 | G13: Raw Cutting | H13: S32 | I13: Other Support of Production | J13: FINISHING | K13: Không có bomtime chuyền UV | L13: HC tăng ca (OT 4 giờ) | M13: 0.64583333 | N13: 0.8125 | O13: =(N13-M13)*24 -> 4 | P13: 6 | Q13: =P13*O13 -> 24 | R13: File UV (báo cáo ngày)
A14: ="W"&WEEKNUM(B14,21) -> W41 | B14: 46303 | C14: RH9949F425 | E14: 1 | G14: Raw Cutting | H14: S32 | I14: Other Support of Production | J14: MACHINING | K14: Beam saw - phát sinh (chi tiết P08-1) | L14: STT 292 | M14: 0.79166667 | N14: 0.79305556 | O14: =(N14-M14)*24 -> 0.033333333 | P14: 3 | Q14: =P14*O14 -> 0.1 | R14: File Beam saw
A15: ="W"&WEEKNUM(B15,21) -> W41 | B15: 46303 | C15: RH9339F423 | E15: 1 | G15: Raw Cutting | H15: S32 | I15: Other Support of Production | J15: MACHINING | K15: Beam saw - phát sinh (chi tiết P01-1) | L15: STT 293 | M15: 0.79513889 | N15: 0.79652778 | O15: =(N15-M15)*24 -> 0.033333333 | P15: 3 | Q15: =P15*O15 -> 0.1 | R15: File Beam saw
A16: ="W"&WEEKNUM(B16,21) -> W41 | B16: 46304 | G16: Raw Cutting | H16: S32 | I16: Other Support of Production | J16: FINISHING | K16: Không có bomtime chuyền UV | L16: HC làm việc (ca thường) | M16: 0.3125 | N16: 0.64583333 | O16: =(N16-M16)*24 -> 8 | P16: 12 | Q16: =P16*O16 -> 96 | R16: File UV (báo cáo ngày)
A17: ="W"&WEEKNUM(B17,21) -> W41 | B17: 46304 | G17: Raw Cutting | H17: S32 | I17: Other Support of Production | J17: FINISHING | K17: Không có bomtime chuyền UV | L17: HC tăng ca (OT 4 giờ) | M17: 0.64583333 | N17: 0.8125 | O17: =(N17-M17)*24 -> 4 | P17: 9 | Q17: =P17*O17 -> 36 | R17: File UV (báo cáo ngày)
A18: ="W"&WEEKNUM(B18,21) -> W41 | B18: 46304 | C18: RH7340F383 | E18: 1 | G18: Raw Cutting | H18: S32 | I18: Other Support of Production | J18: MACHINING | K18: Beam saw - phát sinh (chi tiết A3-S01) | L18: STT 294 | M18: 0.33333333 | N18: 0.33472222 | O18: =(N18-M18)*24 -> 0.033333333 | P18: 3 | Q18: =P18*O18 -> 0.1 | R18: File Beam saw
A19: ="W"&WEEKNUM(B19,21) -> W41 | B19: 46304 | C19: RH7150F409 | E19: 1 | G19: Raw Cutting | H19: S32 | I19: Other Support of Production | J19: MACHINING | K19: Beam saw - phát sinh (chi tiết P01) | L19: STT 295 | M19: 0.33472222 | N19: 0.33611111 | O19: =(N19-M19)*24 -> 0.033333333 | P19: 3 | Q19: =P19*O19 -> 0.1 | R19: File Beam saw
A20: ="W"&WEEKNUM(B20,21) -> W41 | B20: 46304 | C20: AR1368F1330 | E20: 4 | G20: Raw Cutting | H20: S32 | I20: Other Support of Production | J20: QA/QC/TESTING | K20: Beam saw - phát sinh (chi tiết P12) | L20: Charge to: QA do không test lúc sample | M20: 0.34027778 | N20: 0.34444444 | O20: =(N20-M20)*24 -> 0.1 | P20: 3 | Q20: =P20*O20 -> 0.3 | R20: File Beam saw
A21: ="W"&WEEKNUM(B21,21) -> W41 | B21: 46304 | C21: AR1001F1001 | E21: 1 | G21: Raw Cutting | H21: S32 | I21: Other Support of Production | J21: MACHINING | K21: Beam saw - phát sinh (chi tiết A1-S02) | L21: STT 297 | M21: 0.75 | N21: 0.75138889 | O21: =(N21-M21)*24 -> 0.033333333 | P21: 3 | Q21: =P21*O21 -> 0.1 | R21: File Beam saw
A22: ="W"&WEEKNUM(B22,21) -> W41 | B22: 46305 | G22: Raw Cutting | H22: S32 | I22: Other Support of Production | J22: FINISHING | K22: Không có bomtime chuyền UV | L22: HC làm việc (ca thường) | M22: 0.3125 | N22: 0.64583333 | O22: =(N22-M22)*24 -> 8 | P22: 10 | Q22: =P22*O22 -> 80 | R22: File UV (báo cáo ngày)
A23: ="W"&WEEKNUM(B23,21) -> W41 | B23: 46305 | G23: Raw Cutting | H23: S32 | I23: Other Support of Production | J23: FINISHING | K23: Không có bomtime chuyền UV | L23: HC tăng ca (OT 4 giờ) | M23: 0.64583333 | N23: 0.8125 | O23: =(N23-M23)*24 -> 4 | P23: 9 | Q23: =P23*O23 -> 36 | R23: File UV (báo cáo ngày)
A24: ="W"&WEEKNUM(B24,21) -> W41 | B24: 46305 | C24: code 516+code 231 | E24: 150 | G24: Raw Cutting | H24: S32 | I24: Other Support of Production | J24: TECHNICAL FINISHING | K24: Làm mẫu (veneer) | L24: 2 mã (code 516, code 231), 1 ca | M24: 0.375 | N24: 0.4375 | O24: =(N24-M24)*24 -> 1.5 | P24: 2 | Q24: =P24*O24 -> 3 | R24: File Veneer
A25: ="W"&WEEKNUM(B25,21) -> W41 | B25: 46306 | G25: Raw Cutting | H25: S32 | I25: Other Support of Production | J25: FINISHING | K25: Không có bomtime chuyền UV | L25: HC làm việc (ca thường) | M25: 0.3125 | N25: 0.64583333 | O25: =(N25-M25)*24 -> 8 | P25: 9 | Q25: =P25*O25 -> 72 | R25: File UV (báo cáo ngày)
A26: ="W"&WEEKNUM(B26,21) -> W42 | B26: 46307 | G26: Raw Cutting | H26: S32 | I26: Other Support of Production | J26: FINISHING | K26: Không có bomtime chuyền UV | L26: HC làm việc (ca thường) | M26: 0.3125 | N26: 0.64583333 | O26: =(N26-M26)*24 -> 8 | P26: 11 | Q26: =P26*O26 -> 88 | R26: File UV (báo cáo ngày)
A27: ="W"&WEEKNUM(B27,21) -> W42 | B27: 46307 | G27: Raw Cutting | H27: S32 | I27: Other Support of Production | J27: FINISHING | K27: Không có bomtime chuyền UV | L27: HC tăng ca (OT 4 giờ) | M27: 0.64583333 | N27: 0.8125 | O27: =(N27-M27)*24 -> 4 | P27: 11 | Q27: =P27*O27 -> 44 | R27: File UV (báo cáo ngày)
A28: ="W"&WEEKNUM(B28,21) -> W42 | B28: 46307 | G28: Raw Cutting | H28: S32 | I28: Other Support of Production | J28: QA/QC/TESTING | K28: Phát sinh khu vực UV - SLAT (23 mã hàng) | L28: Charge to: QC A HIẾU; mã hàng xem sheet Chi tiết | M28: 0.3125 | N28: 0.625 | O28: =(N28-M28)*24 -> 7.5 | P28: 1 | Q28: =P28*O28 -> 7.5 | R28: File UV (phát sinh)
A29: ="W"&WEEKNUM(B29,21) -> W42 | B29: 46307 | C29: RH11-1119-0129-41797+RH11-1179-0129-40474+RH11-4136-0129-40505 (+20 mã) | E29: 2522 | G29: Raw Cutting | H29: S32 | I29: Other Support of Production | J29: QA/QC/TESTING | K29: Phát sinh khu vực UV - SLAT (23 mã hàng) | L29: Charge to: QC A HIẾU; mã hàng xem sheet Chi tiết | M29: 0.39583333 | N29: 0.83333333 | O29: =(N29-M29)*24 -> 10.5 | P29: 1 | Q29: =P29*O29 -> 10.5 | R29: File UV (phát sinh)
A30: ="W"&WEEKNUM(B30,21) -> W42 | B30: 46307 | G30: Assembly | H30: S32 | I30: Other Support of Production | J30: FINISHING | K30: Không có bomtime sơn lòng trong | L30: Thợ sơn lòng trong tủ - hỗ trợ Fin | M30: 0.3125 | N30: 0.8125 | O30: =(N30-M30)*24 -> 12 | P30: 12 | Q30: =P30*O30 -> 144 | R30: Hình: thợ sơn
A31: ="W"&WEEKNUM(B31,21) -> W42 | B31: 46308 | G31: Raw Cutting | H31: S32 | I31: Other Support of Production | J31: FINISHING | K31: Không có bomtime chuyền UV | L31: HC làm việc (ca thường) | M31: 0.3125 | N31: 0.64583333 | O31: =(N31-M31)*24 -> 8 | P31: 12 | Q31: =P31*O31 -> 96 | R31: File UV (báo cáo ngày)
A32: ="W"&WEEKNUM(B32,21) -> W42 | B32: 46308 | G32: Raw Cutting | H32: S32 | I32: Other Support of Production | J32: FINISHING | K32: Không có bomtime chuyền UV | L32: HC tăng ca (OT 4 giờ) | M32: 0.64583333 | N32: 0.8125 | O32: =(N32-M32)*24 -> 4 | P32: 11 | Q32: =P32*O32 -> 44 | R32: File UV (báo cáo ngày)
A33: ="W"&WEEKNUM(B33,21) -> W42 | B33: 46308 | C33: AR12-1137-1404-R0000 | E33: 9 | G33: Raw Cutting | H33: S32 | I33: Other Support of Production | J33: TECHNICAL FINISHING | K33: Phát sinh khu vực UV - Back Panel | L33: Charge to: TF | M33: 0.64583333 | N33: 0.83333333 | O33: =(N33-M33)*24 -> 4.5 | P33: 1 | Q33: =P33*O33 -> 4.5 | R33: File UV (phát sinh)
A34: ="W"&WEEKNUM(B34,21) -> W42 | B34: 46308 | G34: Assembly | H34: S32 | I34: Other Support of Production | J34: FINISHING | K34: Không có bomtime sơn lòng trong | L34: Thợ sơn lòng trong tủ - hỗ trợ Fin | M34: 0.3125 | N34: 0.8125 | O34: =(N34-M34)*24 -> 12 | P34: 12 | Q34: =P34*O34 -> 144 | R34: Hình: thợ sơn
A35: ="W"&WEEKNUM(B35,21) -> W42 | B35: 46309 | G35: Raw Cutting | H35: S32 | I35: Other Support of Production | J35: FINISHING | K35: Không có bomtime chuyền UV | L35: HC làm việc (ca thường) | M35: 0.3125 | N35: 0.64583333 | O35: =(N35-M35)*24 -> 8 | P35: 12 | Q35: =P35*O35 -> 96 | R35: File UV (báo cáo ngày)
A36: ="W"&WEEKNUM(B36,21) -> W42 | B36: 46309 | G36: Raw Cutting | H36: S32 | I36: Other Support of Production | J36: FINISHING | K36: Không có bomtime chuyền UV | L36: HC tăng ca (OT 4 giờ) | M36: 0.64583333 | N36: 0.8125 | O36: =(N36-M36)*24 -> 4 | P36: 9 | Q36: =P36*O36 -> 36 | R36: File UV (báo cáo ngày)
A37: ="W"&WEEKNUM(B37,21) -> W42 | B37: 46309 | C37: AR1069F1233 | E37: 100 | G37: Machining | H37: S32 | I37: Other Support of Production | J37: ME | K37: Hỗ trợ sửa hàng MAC - chạy nhỏ lại mộng theo routing | L37: Chi tiết A5-S2, 100 cây | M37: 0.375 | N37: 0.41666667 | O37: =(N37-M37)*24 -> 1 | P37: 2 | Q37: =P37*O37 -> 2 | R37: File sửa hàng MAC
A38: ="W"&WEEKNUM(B38,21) -> W42 | B38: 46309 | G38: Assembly | H38: S32 | I38: Other Support of Production | J38: FINISHING | K38: Không có bomtime sơn lòng trong | L38: Thợ sơn lòng trong tủ - hỗ trợ Fin | M38: 0.3125 | N38: 0.8125 | O38: =(N38-M38)*24 -> 12 | P38: 12 | Q38: =P38*O38 -> 144 | R38: Hình: thợ sơn
A39: ="W"&WEEKNUM(B39,21) -> W42 | B39: 46310 | G39: Raw Cutting | H39: S32 | I39: Other Support of Production | J39: FINISHING | K39: Không có bomtime chuyền UV | L39: HC làm việc (ca thường) | M39: 0.3125 | N39: 0.64583333 | O39: =(N39-M39)*24 -> 8 | P39: 12 | Q39: =P39*O39 -> 96 | R39: File UV (báo cáo ngày)
A40: ="W"&WEEKNUM(B40,21) -> W42 | B40: 46310 | G40: Raw Cutting | H40: S32 | I40: Other Support of Production | J40: FINISHING | K40: Không có bomtime chuyền UV | L40: HC tăng ca (OT 4 giờ) | M40: 0.64583333 | N40: 0.8125 | O40: =(N40-M40)*24 -> 4 | P40: 9 | Q40: =P40*O40 -> 36 | R40: File UV (báo cáo ngày)
...

Sheet Theo ngày
A1: GIỜ CÔNG S32 THEO NGÀY VÀ THEO NGUỒN
A3: Ngày | B3: Thứ | C3: Tuần | D3: File Ép nóng | E3: File UV (báo cáo ngày) | F3: File Beam saw | G3: File Veneer | H3: File sửa hàng MAC | I3: File UV (phát sinh) | J3: Hình: thợ sơn | K3: Hình: cào cước | L3: Hình: bắn cát | M3: Hình: INLAY (RESIN) | N3: Tổng ngày
A4: 46300 | B4: Thứ Hai | C4: ="W"&WEEKNUM(A4,21) -> W41 | D4: =SUMIFS('S32 5-10 đến 29-10'!$Q$3:$Q$103,'S32 5-10 đến 29-10'!$B$3:$B$103,$A4,'S32 5-10 đến 29-10'!$R$3:$R$103,D$3) -> 46 | E4: =SUMIFS('S32 5-10 đến 29-10'!$Q$3:$Q$103,'S32 5-10 đến 29-10'!$B$3:$B$103,$A4,'S32 5-10 đến 29-10'!$R$3:$R$103,E$3) -> 120 | F4: =SUMIFS('S32 5-10 đến 29-10'!$Q$3:$Q$103,'S32 5-10 đến 29-10'!$B$3:$B$103,$A4,'S32 5-10 đến 29-10'!$R$3:$R$103,F$3) -> 0 | G4: =SUMIFS('S32 5-10 đến 29-10'!$Q$3:$Q$103,'S32 5-10 đến 29-10'!$B$3:$B$103,$A4,'S32 5-10 đến 29-10'!$R$3:$R$103,G$3) -> 0 | H4: =SUMIFS('S32 5-10 đến 29-10'!$Q$3:$Q$103,'S32 5-10 đến 29-10'!$B$3:$B$103,$A4,'S32 5-10 đến 29-10'!$R$3:$R$103,H$3) -> 0 | I4: =SUMIFS('S32 5-10 đến 29-10'!$Q$3:$Q$103,'S32 5-10 đến 29-10'!$B$3:$B$103,$A4,'S32 5-10 đến 29-10'!$R$3:$R$103,I$3) -> 0 | J4: =SUMIFS('S32 5-10 đến 29-10'!$Q$3:$Q$103,'S32 5-10 đến 29-10'!$B$3:$B$103,$A4,'S32 5-10 đến 29-10'!$R$3:$R$103,J$3) -> 0 | K4: =SUMIFS('S32 5-10 đến 29-10'!$Q$3:$Q$103,'S32 5-10 đến 29-10'!$B$3:$B$103,$A4,'S32 5-10 đến 29-10'!$R$3:$R$103,K$3) -> 0 | ... M4: =SUMIFS('S32 5-10 đến 29-10'!$Q$3:$Q$103,'S32 5-10 đến 29-10'!$B$3:$B$103,$A4,'S32 5-10 đến 29-10'!$R$3:$R$103,M$3) -> 0 | N4: =SUM(D4:M4) -> 166
A5: 46301 | B5: Thứ Ba | C5: ="W"&WEEKNUM(A5,21) -> W41 | D5: =SUMIFS('S32 5-10 đến 29-10'!$Q$3:$Q$103,'S32 5-10 đến 29-10'!$B$3:$B$103,$A5,'S32 5-10 đến 29-10'!$R$3:$R$103,D$3) -> 55 | E5: =SUMIFS('S32 5-10 đến 29-10'!$Q$3:$Q$103,'S32 5-10 đến 29-10'!$B$3:$B$103,$A5,'S32 5-10 đến 29-10'!$R$3:$R$103,E$3) -> 120 | F5: =SUMIFS('S32 5-10 đến 29-10'!$Q$3:$Q$103,'S32 5-10 đến 29-10'!$B$3:$B$103,$A5,'S32 5-10 đến 29-10'!$R$3:$R$103,F$3) -> 0 | G5: =SUMIFS('S32 5-10 đến 29-10'!$Q$3:$Q$103,'S32 5-10 đến 29-10'!$B$3:$B$103,$A5,'S32 5-10 đến 29-10'!$R$3:$R$103,G$3) -> 0 | H5: =SUMIFS('S32 5-10 đến 29-10'!$Q$3:$Q$103,'S32 5-10 đến 29-10'!$B$3:$B$103,$A5,'S32 5-10 đến 29-10'!$R$3:$R$103,H$3) -> 0 | I5: =SUMIFS('S32 5-10 đến 29-10'!$Q$3:$Q$103,'S32 5-10 đến 29-10'!$B$3:$B$103,$A5,'S32 5-10 đến 29-10'!$R$3:$R$103,I$3) -> 0 | J5: =SUMIFS('S32 5-10 đến 29-10'!$Q$3:$Q$103,'S32 5-10 đến 29-10'!$B$3:$B$103,$A5,'S32 5-10 đến 29-10'!$R$3:$R$103,J$3) -> 0 | K5: =SUMIFS('S32 5-10 đến 29-10'!$Q$3:$Q$103,'S32 5-10 đến 29-10'!$B$3:$B$103,$A5,'S32 5-10 đến 29-10'!$R$3:$R$103,K$3) -> 0 | ... M5: =SUMIFS('S32 5-10 đến 29-10'!$Q$3:$Q$103,'S32 5-10 đến 29-10'!$B$3:$B$103,$A5,'S32 5-10 đến 29-10'!$R$3:$R$103,M$3) -> 0 | N5: =SUM(D5:M5) -> 175
A6: 46302 | B6: Thứ Tư | C6: ="W"&WEEKNUM(A6,21) -> W41 | D6: =SUMIFS('S32 5-10 đến 29-10'!$Q$3:$Q$103,'S32 5-10 đến 29-10'!$B$3:$B$103,$A6,'S32 5-10 đến 29-10'!$R$3:$R$103,D$3) -> 0 | E6: =SUMIFS('S32 5-10 đến 29-10'!$Q$3:$Q$103,'S32 5-10 đến 29-10'!$B$3:$B$103,$A6,'S32 5-10 đến 29-10'!$R$3:$R$103,E$3) -> 112 | F6: =SUMIFS('S32 5-10 đến 29-10'!$Q$3:$Q$103,'S32 5-10 đến 29-10'!$B$3:$B$103,$A6,'S32 5-10 đến 29-10'!$R$3:$R$103,F$3) -> 0 | G6: =SUMIFS('S32 5-10 đến 29-10'!$Q$3:$Q$103,'S32 5-10 đến 29-10'!$B$3:$B$103,$A6,'S32 5-10 đến 29-10'!$R$3:$R$103,G$3) -> 0 | H6: =SUMIFS('S32 5-10 đến 29-10'!$Q$3:$Q$103,'S32 5-10 đến 29-10'!$B$3:$B$103,$A6,'S32 5-10 đến 29-10'!$R$3:$R$103,H$3) -> 0 | I6: =SUMIFS('S32 5-10 đến 29-10'!$Q$3:$Q$103,'S32 5-10 đến 29-10'!$B$3:$B$103,$A6,'S32 5-10 đến 29-10'!$R$3:$R$103,I$3) -> 0 | J6: =SUMIFS('S32 5-10 đến 29-10'!$Q$3:$Q$103,'S32 5-10 đến 29-10'!$B$3:$B$103,$A6,'S32 5-10 đến 29-10'!$R$3:$R$103,J$3) -> 0 | K6: =SUMIFS('S32 5-10 đến 29-10'!$Q$3:$Q$103,'S32 5-10 đến 29-10'!$B$3:$B$103,$A6,'S32 5-10 đến 29-10'!$R$3:$R$103,K$3) -> 0 | ... M6: =SUMIFS('S32 5-10 đến 29-10'!$Q$3:$Q$103,'S32 5-10 đến 29-10'!$B$3:$B$103,$A6,'S32 5-10 đến 29-10'!$R$3:$R$103,M$3) -> 0 | N6: =SUM(D6:M6) -> 112
A7: 46303 | B7: Thứ Năm | C7: ="W"&WEEKNUM(A7,21) -> W41 | D7: =SUMIFS('S32 5-10 đến 29-10'!$Q$3:$Q$103,'S32 5-10 đến 29-10'!$B$3:$B$103,$A7,'S32 5-10 đến 29-10'!$R$3:$R$103,D$3) -> 0 | E7: =SUMIFS('S32 5-10 đến 29-10'!$Q$3:$Q$103,'S32 5-10 đến 29-10'!$B$3:$B$103,$A7,'S32 5-10 đến 29-10'!$R$3:$R$103,E$3) -> 104 | F7: =SUMIFS('S32 5-10 đến 29-10'!$Q$3:$Q$103,'S32 5-10 đến 29-10'!$B$3:$B$103,$A7,'S32 5-10 đến 29-10'!$R$3:$R$103,F$3) -> 0.2 | G7: =SUMIFS('S32 5-10 đến 29-10'!$Q$3:$Q$103,'S32 5-10 đến 29-10'!$B$3:$B$103,$A7,'S32 5-10 đến 29-10'!$R$3:$R$103,G$3) -> 0 | H7: =SUMIFS('S32 5-10 đến 29-10'!$Q$3:$Q$103,'S32 5-10 đến 29-10'!$B$3:$B$103,$A7,'S32 5-10 đến 29-10'!$R$3:$R$103,H$3) -> 0 | I7: =SUMIFS('S32 5-10 đến 29-10'!$Q$3:$Q$103,'S32 5-10 đến 29-10'!$B$3:$B$103,$A7,'S32 5-10 đến 29-10'!$R$3:$R$103,I$3) -> 0 | J7: =SUMIFS('S32 5-10 đến 29-10'!$Q$3:$Q$103,'S32 5-10 đến 29-10'!$B$3:$B$103,$A7,'S32 5-10 đến 29-10'!$R$3:$R$103,J$3) -> 0 | K7: =SUMIFS('S32 5-10 đến 29-10'!$Q$3:$Q$103,'S32 5-10 đến 29-10'!$B$3:$B$103,$A7,'S32 5-10 đến 29-10'!$R$3:$R$103,K$3) -> 0 | ... M7: =SUMIFS('S32 5-10 đến 29-10'!$Q$3:$Q$103,'S32 5-10 đến 29-10'!$B$3:$B$103,$A7,'S32 5-10 đến 29-10'!$R$3:$R$103,M$3) -> 0 | N7: =SUM(D7:M7) -> 104.2
A8: 46304 | B8: Thứ Sáu | C8: ="W"&WEEKNUM(A8,21) -> W41 | D8: =SUMIFS('S32 5-10 đến 29-10'!$Q$3:$Q$103,'S32 5-10 đến 29-10'!$B$3:$B$103,$A8,'S32 5-10 đến 29-10'!$R$3:$R$103,D$3) -> 0 | E8: =SUMIFS('S32 5-10 đến 29-10'!$Q$3:$Q$103,'S32 5-10 đến 29-10'!$B$3:$B$103,$A8,'S32 5-10 đến 29-10'!$R$3:$R$103,E$3) -> 132 | F8: =SUMIFS('S32 5-10 đến 29-10'!$Q$3:$Q$103,'S32 5-10 đến 29-10'!$B$3:$B$103,$A8,'S32 5-10 đến 29-10'!$R$3:$R$103,F$3) -> 0.6 | G8: =SUMIFS('S32 5-10 đến 29-10'!$Q$3:$Q$103,'S32 5-10 đến 29-10'!$B$3:$B$103,$A8,'S32 5-10 đến 29-10'!$R$3:$R$103,G$3) -> 0 | H8: =SUMIFS('S32 5-10 đến 29-10'!$Q$3:$Q$103,'S32 5-10 đến 29-10'!$B$3:$B$103,$A8,'S32 5-10 đến 29-10'!$R$3:$R$103,H$3) -> 0 | I8: =SUMIFS('S32 5-10 đến 29-10'!$Q$3:$Q$103,'S32 5-10 đến 29-10'!$B$3:$B$103,$A8,'S32 5-10 đến 29-10'!$R$3:$R$103,I$3) -> 0 | J8: =SUMIFS('S32 5-10 đến 29-10'!$Q$3:$Q$103,'S32 5-10 đến 29-10'!$B$3:$B$103,$A8,'S32 5-10 đến 29-10'!$R$3:$R$103,J$3) -> 0 | K8: =SUMIFS('S32 5-10 đến 29-10'!$Q$3:$Q$103,'S32 5-10 đến 29-10'!$B$3:$B$103,$A8,'S32 5-10 đến 29-10'!$R$3:$R$103,K$3) -> 0 | ... M8: =SUMIFS('S32 5-10 đến 29-10'!$Q$3:$Q$103,'S32 5-10 đến 29-10'!$B$3:$B$103,$A8,'S32 5-10 đến 29-10'!$R$3:$R$103,M$3) -> 0 | N8: =SUM(D8:M8) -> 132.6
A9: 46305 | B9: Thứ Bảy | C9: ="W"&WEEKNUM(A9,21) -> W41 | D9: =SUMIFS('S32 5-10 đến 29-10'!$Q$3:$Q$103,'S32 5-10 đến 29-10'!$B$3:$B$103,$A9,'S32 5-10 đến 29-10'!$R$3:$R$103,D$3) -> 0 | E9: =SUMIFS('S32 5-10 đến 29-10'!$Q$3:$Q$103,'S32 5-10 đến 29-10'!$B$3:$B$103,$A9,'S32 5-10 đến 29-10'!$R$3:$R$103,E$3) -> 116 | F9: =SUMIFS('S32 5-10 đến 29-10'!$Q$3:$Q$103,'S32 5-10 đến 29-10'!$B$3:$B$103,$A9,'S32 5-10 đến 29-10'!$R$3:$R$103,F$3) -> 0 | G9: =SUMIFS('S32 5-10 đến 29-10'!$Q$3:$Q$103,'S32 5-10 đến 29-10'!$B$3:$B$103,$A9,'S32 5-10 đến 29-10'!$R$3:$R$103,G$3) -> 3 | H9: =SUMIFS('S32 5-10 đến 29-10'!$Q$3:$Q$103,'S32 5-10 đến 29-10'!$B$3:$B$103,$A9,'S32 5-10 đến 29-10'!$R$3:$R$103,H$3) -> 0 | I9: =SUMIFS('S32 5-10 đến 29-10'!$Q$3:$Q$103,'S32 5-10 đến 29-10'!$B$3:$B$103,$A9,'S32 5-10 đến 29-10'!$R$3:$R$103,I$3) -> 0 | J9: =SUMIFS('S32 5-10 đến 29-10'!$Q$3:$Q$103,'S32 5-10 đến 29-10'!$B$3:$B$103,$A9,'S32 5-10 đến 29-10'!$R$3:$R$103,J$3) -> 0 | K9: =SUMIFS('S32 5-10 đến 29-10'!$Q$3:$Q$103,'S32 5-10 đến 29-10'!$B$3:$B$103,$A9,'S32 5-10 đến 29-10'!$R$3:$R$103,K$3) -> 0 | ... M9: =SUMIFS('S32 5-10 đến 29-10'!$Q$3:$Q$103,'S32 5-10 đến 29-10'!$B$3:$B$103,$A9,'S32 5-10 đến 29-10'!$R$3:$R$103,M$3) -> 0 | N9: =SUM(D9:M9) -> 119
A10: 46306 | B10: Chủ nhật | C10: ="W"&WEEKNUM(A10,21) -> W41 | D10: =SUMIFS('S32 5-10 đến 29-10'!$Q$3:$Q$103,'S32 5-10 đến 29-10'!$B$3:$B$103,$A10,'S32 5-10 đến 29-10'!$R$3:$R$103,D$3) -> 0 | E10: =SUMIFS('S32 5-10 đến 29-10'!$Q$3:$Q$103,'S32 5-10 đến 29-10'!$B$3:$B$103,$A10,'S32 5-10 đến 29-10'!$R$3:$R$103,E$3) -> 72 | F10: =SUMIFS('S32 5-10 đến 29-10'!$Q$3:$Q$103,'S32 5-10 đến 29-10'!$B$3:$B$103,$A10,'S32 5-10 đến 29-10'!$R$3:$R$103,F$3) -> 0 | G10: =SUMIFS('S32 5-10 đến 29-10'!$Q$3:$Q$103,'S32 5-10 đến 29-10'!$B$3:$B$103,$A10,'S32 5-10 đến 29-10'!$R$3:$R$103,G$3) -> 0 | H10: =SUMIFS('S32 5-10 đến 29-10'!$Q$3:$Q$103,'S32 5-10 đến 29-10'!$B$3:$B$103,$A10,'S32 5-10 đến 29-10'!$R$3:$R$103,H$3) -> 0 | I10: =SUMIFS('S32 5-10 đến 29-10'!$Q$3:$Q$103,'S32 5-10 đến 29-10'!$B$3:$B$103,$A10,'S32 5-10 đến 29-10'!$R$3:$R$103,I$3) -> 0 | J10: =SUMIFS('S32 5-10 đến 29-10'!$Q$3:$Q$103,'S32 5-10 đến 29-10'!$B$3:$B$103,$A10,'S32 5-10 đến 29-10'!$R$3:$R$103,J$3) -> 0 | K10: =SUMIFS('S32 5-10 đến 29-10'!$Q$3:$Q$103,'S32 5-10 đến 29-10'!$B$3:$B$103,$A10,'S32 5-10 đến 29-10'!$R$3:$R$103,K$3) -> 0 | ... M10: =SUMIFS('S32 5-10 đến 29-10'!$Q$3:$Q$103,'S32 5-10 đến 29-10'!$B$3:$B$103,$A10,'S32 5-10 đến 29-10'!$R$3:$R$103,M$3) -> 0 | N10: =SUM(D10:M10) -> 72
A11: 46307 | B11: Thứ Hai | C11: ="W"&WEEKNUM(A11,21) -> W42 | D11: =SUMIFS('S32 5-10 đến 29-10'!$Q$3:$Q$103,'S32 5-10 đến 29-10'!$B$3:$B$103,$A11,'S32 5-10 đến 29-10'!$R$3:$R$103,D$3) -> 0 | E11: =SUMIFS('S32 5-10 đến 29-10'!$Q$3:$Q$103,'S32 5-10 đến 29-10'!$B$3:$B$103,$A11,'S32 5-10 đến 29-10'!$R$3:$R$103,E$3) -> 132 | F11: =SUMIFS('S32 5-10 đến 29-10'!$Q$3:$Q$103,'S32 5-10 đến 29-10'!$B$3:$B$103,$A11,'S32 5-10 đến 29-10'!$R$3:$R$103,F$3) -> 0 | G11: =SUMIFS('S32 5-10 đến 29-10'!$Q$3:$Q$103,'S32 5-10 đến 29-10'!$B$3:$B$103,$A11,'S32 5-10 đến 29-10'!$R$3:$R$103,G$3) -> 0 | H11: =SUMIFS('S32 5-10 đến 29-10'!$Q$3:$Q$103,'S32 5-10 đến 29-10'!$B$3:$B$103,$A11,'S32 5-10 đến 29-10'!$R$3:$R$103,H$3) -> 0 | I11: =SUMIFS('S32 5-10 đến 29-10'!$Q$3:$Q$103,'S32 5-10 đến 29-10'!$B$3:$B$103,$A11,'S32 5-10 đến 29-10'!$R$3:$R$103,I$3) -> 18 | J11: =SUMIFS('S32 5-10 đến 29-10'!$Q$3:$Q$103,'S32 5-10 đến 29-10'!$B$3:$B$103,$A11,'S32 5-10 đến 29-10'!$R$3:$R$103,J$3) -> 144 | K11: =SUMIFS('S32 5-10 đến 29-10'!$Q$3:$Q$103,'S32 5-10 đến 29-10'!$B$3:$B$103,$A11,'S32 5-10 đến 29-10'!$R$3:$R$103,K$3) -> 0 | ... M11: =SUMIFS('S32 5-10 đến 29-10'!$Q$3:$Q$103,'S32 5-10 đến 29-10'!$B$3:$B$103,$A11,'S32 5-10 đến 29-10'!$R$3:$R$103,M$3) -> 0 | N11: =SUM(D11:M11) -> 294
A12: 46308 | B12: Thứ Ba | C12: ="W"&WEEKNUM(A12,21) -> W42 | D12: =SUMIFS('S32 5-10 đến 29-10'!$Q$3:$Q$103,'S32 5-10 đến 29-10'!$B$3:$B$103,$A12,'S32 5-10 đến 29-10'!$R$3:$R$103,D$3) -> 0 | E12: =SUMIFS('S32 5-10 đến 29-10'!$Q$3:$Q$103,'S32 5-10 đến 29-10'!$B$3:$B$103,$A12,'S32 5-10 đến 29-10'!$R$3:$R$103,E$3) -> 140 | F12: =SUMIFS('S32 5-10 đến 29-10'!$Q$3:$Q$103,'S32 5-10 đến 29-10'!$B$3:$B$103,$A12,'S32 5-10 đến 29-10'!$R$3:$R$103,F$3) -> 0 | G12: =SUMIFS('S32 5-10 đến 29-10'!$Q$3:$Q$103,'S32 5-10 đến 29-10'!$B$3:$B$103,$A12,'S32 5-10 đến 29-10'!$R$3:$R$103,G$3) -> 0 | H12: =SUMIFS('S32 5-10 đến 29-10'!$Q$3:$Q$103,'S32 5-10 đến 29-10'!$B$3:$B$103,$A12,'S32 5-10 đến 29-10'!$R$3:$R$103,H$3) -> 0 | I12: =SUMIFS('S32 5-10 đến 29-10'!$Q$3:$Q$103,'S32 5-10 đến 29-10'!$B$3:$B$103,$A12,'S32 5-10 đến 29-10'!$R$3:$R$103,I$3) -> 4.5 | J12: =SUMIFS('S32 5-10 đến 29-10'!$Q$3:$Q$103,'S32 5-10 đến 29-10'!$B$3:$B$103,$A12,'S32 5-10 đến 29-10'!$R$3:$R$103,J$3) -> 144 | K12: =SUMIFS('S32 5-10 đến 29-10'!$Q$3:$Q$103,'S32 5-10 đến 29-10'!$B$3:$B$103,$A12,'S32 5-10 đến 29-10'!$R$3:$R$103,K$3) -> 0 | ... M12: =SUMIFS('S32 5-10 đến 29-10'!$Q$3:$Q$103,'S32 5-10 đến 29-10'!$B$3:$B$103,$A12,'S32 5-10 đến 29-10'!$R$3:$R$103,M$3) -> 0 | N12: =SUM(D12:M12) -> 288.5
A13: 46309 | B13: Thứ Tư | C13: ="W"&WEEKNUM(A13,21) -> W42 | D13: =SUMIFS('S32 5-10 đến 29-10'!$Q$3:$Q$103,'S32 5-10 đến 29-10'!$B$3:$B$103,$A13,'S32 5-10 đến 29-10'!$R$3:$R$103,D$3) -> 0 | E13: =SUMIFS('S32 5-10 đến 29-10'!$Q$3:$Q$103,'S32 5-10 đến 29-10'!$B$3:$B$103,$A13,'S32 5-10 đến 29-10'!$R$3:$R$103,E$3) -> 132 | F13: =SUMIFS('S32 5-10 đến 29-10'!$Q$3:$Q$103,'S32 5-10 đến 29-10'!$B$3:$B$103,$A13,'S32 5-10 đến 29-10'!$R$3:$R$103,F$3) -> 0 | G13: =SUMIFS('S32 5-10 đến 29-10'!$Q$3:$Q$103,'S32 5-10 đến 29-10'!$B$3:$B$103,$A13,'S32 5-10 đến 29-10'!$R$3:$R$103,G$3) -> 0 | H13: =SUMIFS('S32 5-10 đến 29-10'!$Q$3:$Q$103,'S32 5-10 đến 29-10'!$B$3:$B$103,$A13,'S32 5-10 đến 29-10'!$R$3:$R$103,H$3) -> 2 | I13: =SUMIFS('S32 5-10 đến 29-10'!$Q$3:$Q$103,'S32 5-10 đến 29-10'!$B$3:$B$103,$A13,'S32 5-10 đến 29-10'!$R$3:$R$103,I$3) -> 0 | J13: =SUMIFS('S32 5-10 đến 29-10'!$Q$3:$Q$103,'S32 5-10 đến 29-10'!$B$3:$B$103,$A13,'S32 5-10 đến 29-10'!$R$3:$R$103,J$3) -> 144 | K13: =SUMIFS('S32 5-10 đến 29-10'!$Q$3:$Q$103,'S32 5-10 đến 29-10'!$B$3:$B$103,$A13,'S32 5-10 đến 29-10'!$R$3:$R$103,K$3) -> 0 | ... M13: =SUMIFS('S32 5-10 đến 29-10'!$Q$3:$Q$103,'S32 5-10 đến 29-10'!$B$3:$B$103,$A13,'S32 5-10 đến 29-10'!$R$3:$R$103,M$3) -> 0 | N13: =SUM(D13:M13) -> 278
A14: 46310 | B14: Thứ Năm | C14: ="W"&WEEKNUM(A14,21) -> W42 | D14: =SUMIFS('S32 5-10 đến 29-10'!$Q$3:$Q$103,'S32 5-10 đến 29-10'!$B$3:$B$103,$A14,'S32 5-10 đến 29-10'!$R$3:$R$103,D$3) -> 0 | E14: =SUMIFS('S32 5-10 đến 29-10'!$Q$3:$Q$103,'S32 5-10 đến 29-10'!$B$3:$B$103,$A14,'S32 5-10 đến 29-10'!$R$3:$R$103,E$3) -> 132 | F14: =SUMIFS('S32 5-10 đến 29-10'!$Q$3:$Q$103,'S32 5-10 đến 29-10'!$B$3:$B$103,$A14,'S32 5-10 đến 29-10'!$R$3:$R$103,F$3) -> 0 | G14: =SUMIFS('S32 5-10 đến 29-10'!$Q$3:$Q$103,'S32 5-10 đến 29-10'!$B$3:$B$103,$A14,'S32 5-10 đến 29-10'!$R$3:$R$103,G$3) -> 0.33333333 | H14: =SUMIFS('S32 5-10 đến 29-10'!$Q$3:$Q$103,'S32 5-10 đến 29-10'!$B$3:$B$103,$A14,'S32 5-10 đến 29-10'!$R$3:$R$103,H$3) -> 0 | I14: =SUMIFS('S32 5-10 đến 29-10'!$Q$3:$Q$103,'S32 5-10 đến 29-10'!$B$3:$B$103,$A14,'S32 5-10 đến 29-10'!$R$3:$R$103,I$3) -> 0 | J14: =SUMIFS('S32 5-10 đến 29-10'!$Q$3:$Q$103,'S32 5-10 đến 29-10'!$B$3:$B$103,$A14,'S32 5-10 đến 29-10'!$R$3:$R$103,J$3) -> 144 | K14: =SUMIFS('S32 5-10 đến 29-10'!$Q$3:$Q$103,'S32 5-10 đến 29-10'!$B$3:$B$103,$A14,'S32 5-10 đến 29-10'!$R$3:$R$103,K$3) -> 0 | ... M14: =SUMIFS('S32 5-10 đến 29-10'!$Q$3:$Q$103,'S32 5-10 đến 29-10'!$B$3:$B$103,$A14,'S32 5-10 đến 29-10'!$R$3:$R$103,M$3) -> 0 | N14: =SUM(D14:M14) -> 308.33333
A15: 46311 | B15: Thứ Sáu | C15: ="W"&WEEKNUM(A15,21) -> W42 | D15: =SUMIFS('S32 5-10 đến 29-10'!$Q$3:$Q$103,'S32 5-10 đến 29-10'!$B$3:$B$103,$A15,'S32 5-10 đến 29-10'!$R$3:$R$103,D$3) -> 0 | E15: =SUMIFS('S32 5-10 đến 29-10'!$Q$3:$Q$103,'S32 5-10 đến 29-10'!$B$3:$B$103,$A15,'S32 5-10 đến 29-10'!$R$3:$R$103,E$3) -> 116 | F15: =SUMIFS('S32 5-10 đến 29-10'!$Q$3:$Q$103,'S32 5-10 đến 29-10'!$B$3:$B$103,$A15,'S32 5-10 đến 29-10'!$R$3:$R$103,F$3) -> 0.75 | G15: =SUMIFS('S32 5-10 đến 29-10'!$Q$3:$Q$103,'S32 5-10 đến 29-10'!$B$3:$B$103,$A15,'S32 5-10 đến 29-10'!$R$3:$R$103,G$3) -> 0 | H15: =SUMIFS('S32 5-10 đến 29-10'!$Q$3:$Q$103,'S32 5-10 đến 29-10'!$B$3:$B$103,$A15,'S32 5-10 đến 29-10'!$R$3:$R$103,H$3) -> 0 | I15: =SUMIFS('S32 5-10 đến 29-10'!$Q$3:$Q$103,'S32 5-10 đến 29-10'!$B$3:$B$103,$A15,'S32 5-10 đến 29-10'!$R$3:$R$103,I$3) -> 0 | J15: =SUMIFS('S32 5-10 đến 29-10'!$Q$3:$Q$103,'S32 5-10 đến 29-10'!$B$3:$B$103,$A15,'S32 5-10 đến 29-10'!$R$3:$R$103,J$3) -> 144 | K15: =SUMIFS('S32 5-10 đến 29-10'!$Q$3:$Q$103,'S32 5-10 đến 29-10'!$B$3:$B$103,$A15,'S32 5-10 đến 29-10'!$R$3:$R$103,K$3) -> 9 | ... M15: =SUMIFS('S32 5-10 đến 29-10'!$Q$3:$Q$103,'S32 5-10 đến 29-10'!$B$3:$B$103,$A15,'S32 5-10 đến 29-10'!$R$3:$R$103,M$3) -> 0 | N15: =SUM(D15:M15) -> 269.75
... A26: 46324 | B26: Thứ Năm | C26: ="W"&WEEKNUM(A26,21) -> W44 | D26: =SUMIFS('S32 5-10 đến 29-10'!$Q$3:$Q$103,'S32 5-10 đến 29-10'!$B$3:$B$103,$A26,'S32 5-10 đến 29-10'!$R$3:$R$103,D$3) -> 0 | E26: =SUMIFS('S32 5-10 đến 29-10'!$Q$3:$Q$103,'S32 5-10 đến 29-10'!$B$3:$B$103,$A26,'S32 5-10 đến 29-10'!$R$3:$R$103,E$3) -> 0 | F26: =SUMIFS('S32 5-10 đến 29-10'!$Q$3:$Q$103,'S32 5-10 đến 29-10'!$B$3:$B$103,$A26,'S32 5-10 đến 29-10'!$R$3:$R$103,F$3) -> 0.6 | G26: =SUMIFS('S32 5-10 đến 29-10'!$Q$3:$Q$103,'S32 5-10 đến 29-10'!$B$3:$B$103,$A26,'S32 5-10 đến 29-10'!$R$3:$R$103,G$3) -> 0 | H26: =SUMIFS('S32 5-10 đến 29-10'!$Q$3:$Q$103,'S32 5-10 đến 29-10'!$B$3:$B$103,$A26,'S32 5-10 đến 29-10'!$R$3:$R$103,H$3) -> 0 | I26: =SUMIFS('S32 5-10 đến 29-10'!$Q$3:$Q$103,'S32 5-10 đến 29-10'!$B$3:$B$103,$A26,'S32 5-10 đến 29-10'!$R$3:$R$103,I$3) -> 0 | J26: =SUMIFS('S32 5-10 đến 29-10'!$Q$3:$Q$103,'S32 5-10 đến 29-10'!$B$3:$B$103,$A26,'S32 5-10 đến 29-10'!$R$3:$R$103,J$3) -> 0 | K26: =SUMIFS('S32 5-10 đến 29-10'!$Q$3:$Q$103,'S32 5-10 đến 29-10'!$B$3:$B$103,$A26,'S32 5-10 đến 29-10'!$R$3:$R$103,K$3) -> 0 | ... M26: =SUMIFS('S32 5-10 đến 29-10'!$Q$3:$Q$103,'S32 5-10 đến 29-10'!$B$3:$B$103,$A26,'S32 5-10 đến 29-10'!$R$3:$R$103,M$3) -> 0 | N26: =SUM(D26:M26) -> 0.6
A27: Tổng | D27: =SUM(D4:D26) -> 103 | E27: =SUM(E4:E26) -> 2280 | F27: =SUM(F4:F26) -> 9.2 | G27: =SUM(G4:G26) -> 72.333333 | H27: =SUM(H4:H26) -> 17.6 | I27: =SUM(I4:I26) -> 22.5 | J27: =SUM(J4:J26) -> 1728 | K27: =SUM(K4:K26) -> 55 | ... N27: =SUM(N4:N26) -> 4427.6333
A29: TỔNG THEO TUẦN
A30: Tuần | B30: Giờ công
A31: W41 | B31: =SUMIFS('S32 5-10 đến 29-10'!$Q$3:$Q$103,'S32 5-10 đến 29-10'!$A$3:$A$103,A31) -> 880.8
A32: W42 | B32: =SUMIFS('S32 5-10 đến 29-10'!$Q$3:$Q$103,'S32 5-10 đến 29-10'!$A$3:$A$103,A32) -> 1662.7833
A33: W43 | B33: =SUMIFS('S32 5-10 đến 29-10'!$Q$3:$Q$103,'S32 5-10 đến 29-10'!$A$3:$A$103,A33) -> 1782.85
A34: W44 | B34: =SUMIFS('S32 5-10 đến 29-10'!$Q$3:$Q$103,'S32 5-10 đến 29-10'!$A$3:$A$103,A34) -> 101.2

Sheet Nhập liệu S32
A1: Ngày (Loss Date) | B1: LossTime Code | C1: Notes | D1: Process | E1: Dept In Charge | F1: From | G1: To | H1: Worker Qty | I1: (Tham khảo) Part Number | J1: (Tham khảo) Total Order | K1: (Tham khảo) Ghi chú | L1: (Tham khảo) Nguồn
A2: 46300 | B2: S32 | C2: Hỗ trợ P1 ép nóng | D2: Raw Cutting | E2: OTHERS (INVESTIGATE) | F2: 0.27083333 | G2: 0.4375 | H2: 4 | I2: CZ842F188+CZ842F381+CZ842F409 | J2: 25 | K2: Hỗ trợ P1 (3 mã hàng, 1 ca) | L2: File Ép nóng
A3: 46300 | B3: S32 | C3: Hỗ trợ P1 ép nóng - ép lót | D3: Raw Cutting | E3: OTHERS (INVESTIGATE) | F3: 0.29166667 | G3: 0.54166667 | H3: 5 | I3: CE517F992-TOP+CE592F1222-TOP | J3: 50 | K3: Ép lót (2 mã hàng) | L3: File Ép nóng
A4: 46300 | B4: S32 | C4: Không có bomtime chuyền UV | D4: Raw Cutting | E4: FINISHING | F4: 0.3125 | G4: 0.64583333 | H4: 11 | K4: HC làm việc (ca thường) | L4: File UV (báo cáo ngày)
A5: 46300 | B5: S32 | C5: Không có bomtime chuyền UV | D5: Raw Cutting | E5: FINISHING | F5: 0.64583333 | G5: 0.8125 | H5: 8 | K5: HC tăng ca (OT 4 giờ) | L5: File UV (báo cáo ngày)
A6: 46301 | B6: S32 | C6: Hỗ trợ P1 ép nóng - ép chính | D6: Raw Cutting | E6: OTHERS (INVESTIGATE) | F6: 0.29166667 | G6: 0.75 | H6: 5 | I6: CE517F992-TOP+CE592F1222-TOP | J6: 50 | K6: Ép chính (2 mã hàng) | L6: File Ép nóng
A7: 46301 | B7: S32 | C7: Không có bomtime chuyền UV | D7: Raw Cutting | E7: FINISHING | F7: 0.3125 | G7: 0.64583333 | H7: 11 | K7: HC làm việc (ca thường) | L7: File UV (báo cáo ngày)
A8: 46301 | B8: S32 | C8: Không có bomtime chuyền UV | D8: Raw Cutting | E8: FINISHING | F8: 0.64583333 | G8: 0.8125 | H8: 8 | K8: HC tăng ca (OT 4 giờ) | L8: File UV (báo cáo ngày)
A9: 46302 | B9: S32 | C9: Không có bomtime chuyền UV | D9: Raw Cutting | E9: FINISHING | F9: 0.3125 | G9: 0.64583333 | H9: 10 | K9: HC làm việc (ca thường) | L9: File UV (báo cáo ngày)
A10: 46302 | B10: S32 | C10: Không có bomtime chuyền UV | D10: Raw Cutting | E10: FINISHING | F10: 0.64583333 | G10: 0.8125 | H10: 8 | K10: HC tăng ca (OT 4 giờ) | L10: File UV (báo cáo ngày)
A11: 46303 | B11: S32 | C11: Không có bomtime chuyền UV | D11: Raw Cutting | E11: FINISHING | F11: 0.3125 | G11: 0.64583333 | H11: 10 | K11: HC làm việc (ca thường) | L11: File UV (báo cáo ngày)
A12: 46303 | B12: S32 | C12: Không có bomtime chuyền UV | D12: Raw Cutting | E12: FINISHING | F12: 0.64583333 | G12: 0.8125 | H12: 6 | K12: HC tăng ca (OT 4 giờ) | L12: File UV (báo cáo ngày)
A13: 46303 | B13: S32 | C13: Beam saw - phát sinh (chi tiết P08-1) | D13: Raw Cutting | E13: MACHINING | F13: 0.79166667 | G13: 0.79305556 | H13: 3 | I13: RH9949F425 | J13: 1 | K13: STT 292 | L13: File Beam saw
A14: 46303 | B14: S32 | C14: Beam saw - phát sinh (chi tiết P01-1) | D14: Raw Cutting | E14: MACHINING | F14: 0.79513889 | G14: 0.79652778 | H14: 3 | I14: RH9339F423 | J14: 1 | K14: STT 293 | L14: File Beam saw
A15: 46304 | B15: S32 | C15: Không có bomtime chuyền UV | D15: Raw Cutting | E15: FINISHING | F15: 0.3125 | G15: 0.64583333 | H15: 12 | K15: HC làm việc (ca thường) | L15: File UV (báo cáo ngày)
A16: 46304 | B16: S32 | C16: Không có bomtime chuyền UV | D16: Raw Cutting | E16: FINISHING | F16: 0.64583333 | G16: 0.8125 | H16: 9 | K16: HC tăng ca (OT 4 giờ) | L16: File UV (báo cáo ngày)
A17: 46304 | B17: S32 | C17: Beam saw - phát sinh (chi tiết A3-S01) | D17: Raw Cutting | E17: MACHINING | F17: 0.33333333 | G17: 0.33472222 | H17: 3 | I17: RH7340F383 | J17: 1 | K17: STT 294 | L17: File Beam saw
A18: 46304 | B18: S32 | C18: Beam saw - phát sinh (chi tiết P01) | D18: Raw Cutting | E18: MACHINING | F18: 0.33472222 | G18: 0.33611111 | H18: 3 | I18: RH7150F409 | J18: 1 | K18: STT 295 | L18: File Beam saw
A19: 46304 | B19: S32 | C19: Beam saw - phát sinh (chi tiết P12) | D19: Raw Cutting | E19: QA/QC/TESTING | F19: 0.34027778 | G19: 0.34444444 | H19: 3 | I19: AR1368F1330 | J19: 4 | K19: Charge to: QA do không test lúc sample | L19: File Beam saw
A20: 46304 | B20: S32 | C20: Beam saw - phát sinh (chi tiết A1-S02) | D20: Raw Cutting | E20: MACHINING | F20: 0.75 | G20: 0.75138889 | H20: 3 | I20: AR1001F1001 | J20: 1 | K20: STT 297 | L20: File Beam saw
A21: 46305 | B21: S32 | C21: Không có bomtime chuyền UV | D21: Raw Cutting | E21: FINISHING | F21: 0.3125 | G21: 0.64583333 | H21: 10 | K21: HC làm việc (ca thường) | L21: File UV (báo cáo ngày)
A22: 46305 | B22: S32 | C22: Không có bomtime chuyền UV | D22: Raw Cutting | E22: FINISHING | F22: 0.64583333 | G22: 0.8125 | H22: 9 | K22: HC tăng ca (OT 4 giờ) | L22: File UV (báo cáo ngày)
A23: 46305 | B23: S32 | C23: Làm mẫu (veneer) | D23: Raw Cutting | E23: TECHNICAL FINISHING | F23: 0.375 | G23: 0.4375 | H23: 2 | I23: code 516+code 231 | J23: 150 | K23: 2 mã (code 516, code 231), 1 ca | L23: File Veneer
A24: 46306 | B24: S32 | C24: Không có bomtime chuyền UV | D24: Raw Cutting | E24: FINISHING | F24: 0.3125 | G24: 0.64583333 | H24: 9 | K24: HC làm việc (ca thường) | L24: File UV (báo cáo ngày)
A25: 46307 | B25: S32 | C25: Không có bomtime chuyền UV | D25: Raw Cutting | E25: FINISHING | F25: 0.3125 | G25: 0.64583333 | H25: 11 | K25: HC làm việc (ca thường) | L25: File UV (báo cáo ngày)
A26: 46307 | B26: S32 | C26: Không có bomtime chuyền UV | D26: Raw Cutting | E26: FINISHING | F26: 0.64583333 | G26: 0.8125 | H26: 11 | K26: HC tăng ca (OT 4 giờ) | L26: File UV (báo cáo ngày)
A27: 46307 | B27: S32 | C27: Phát sinh khu vực UV - SLAT (23 mã hàng) | D27: Raw Cutting | E27: QA/QC/TESTING | F27: 0.3125 | G27: 0.625 | H27: 1 | K27: Charge to: QC A HIẾU; mã hàng xem sheet Chi tiết | L27: File UV (phát sinh)
A28: 46307 | B28: S32 | C28: Phát sinh khu vực UV - SLAT (23 mã hàng) | D28: Raw Cutting | E28: QA/QC/TESTING | F28: 0.39583333 | G28: 0.83333333 | H28: 1 | I28: RH11-1119-0129-41797+RH11-1179-0129-40474+RH11-4136-0129-40505 (+20 mã) | J28: 2522 | K28: Charge to: QC A HIẾU; mã hàng xem sheet Chi tiết | L28: File UV (phát sinh)
A29: 46307 | B29: S32 | C29: Không có bomtime sơn lòng trong | D29: Assembly | E29: FINISHING | F29: 0.3125 | G29: 0.8125 | H29: 12 | K29: Thợ sơn lòng trong tủ - hỗ trợ Fin | L29: Hình: thợ sơn
A30: 46308 | B30: S32 | C30: Không có bomtime chuyền UV | D30: Raw Cutting | E30: FINISHING | F30: 0.3125 | G30: 0.64583333 | H30: 12 | K30: HC làm việc (ca thường) | L30: File UV (báo cáo ngày)
A31: 46308 | B31: S32 | C31: Không có bomtime chuyền UV | D31: Raw Cutting | E31: FINISHING | F31: 0.64583333 | G31: 0.8125 | H31: 11 | K31: HC tăng ca (OT 4 giờ) | L31: File UV (báo cáo ngày)
A32: 46308 | B32: S32 | C32: Phát sinh khu vực UV - Back Panel | D32: Raw Cutting | E32: TECHNICAL FINISHING | F32: 0.64583333 | G32: 0.83333333 | H32: 1 | I32: AR12-1137-1404-R0000 | J32: 9 | K32: Charge to: TF | L32: File UV (phát sinh)
A33: 46308 | B33: S32 | C33: Không có bomtime sơn lòng trong | D33: Assembly | E33: FINISHING | F33: 0.3125 | G33: 0.8125 | H33: 12 | K33: Thợ sơn lòng trong tủ - hỗ trợ Fin | L33: Hình: thợ sơn
A34: 46309 | B34: S32 | C34: Không có bomtime chuyền UV | D34: Raw Cutting | E34: FINISHING | F34: 0.3125 | G34: 0.64583333 | H34: 12 | K34: HC làm việc (ca thường) | L34: File UV (báo cáo ngày)
A35: 46309 | B35: S32 | C35: Không có bomtime chuyền UV | D35: Raw Cutting | E35: FINISHING | F35: 0.64583333 | G35: 0.8125 | H35: 9 | K35: HC tăng ca (OT 4 giờ) | L35: File UV (báo cáo ngày)
A36: 46309 | B36: S32 | C36: Hỗ trợ sửa hàng MAC - chạy nhỏ lại mộng theo routing | D36: Machining | E36: ME | F36: 0.375 | G36: 0.41666667 | H36: 2 | I36: AR1069F1233 | J36: 100 | K36: Chi tiết A5-S2, 100 cây | L36: File sửa hàng MAC
A37: 46309 | B37: S32 | C37: Không có bomtime sơn lòng trong | D37: Assembly | E37: FINISHING | F37: 0.3125 | G37: 0.8125 | H37: 12 | K37: Thợ sơn lòng trong tủ - hỗ trợ Fin | L37: Hình: thợ sơn
A38: 46310 | B38: S32 | C38: Không có bomtime chuyền UV | D38: Raw Cutting | E38: FINISHING | F38: 0.3125 | G38: 0.64583333 | H38: 12 | K38: HC làm việc (ca thường) | L38: File UV (báo cáo ngày)
A39: 46310 | B39: S32 | C39: Không có bomtime chuyền UV | D39: Raw Cutting | E39: FINISHING | F39: 0.64583333 | G39: 0.8125 | H39: 9 | K39: HC tăng ca (OT 4 giờ) | L39: File UV (báo cáo ngày)
A40: 46310 | B40: S32 | C40: Làm mẫu (veneer) | D40: Raw Cutting | E40: ME | F40: 0.33333333 | G40: 0.34722222 | H40: 1 | I40: code 229 | J40: 4 | K40: code 229 | L40: File Veneer
...

Sheet Đối chiếu nguồn
A1: ĐỐI CHIẾU GIỜ CÔNG VỚI SỐ GIỜ TRONG FILE/HÌNH NGUỒN
A3: Nguồn | B3: Số giờ trong file/hình nguồn | C3: Giờ công trong bảng S32 | D3: Chênh lệch | E3: Kết quả
A4: File Beam saw | B4: 9.2 | C4: =SUMIFS('S32 5-10 đến 29-10'!$Q$3:$Q$103,'S32 5-10 đến 29-10'!$R$3:$R$103,A4) -> 9.2 | D4: =C4-B4 -> 0 | E4: =IF(ABS(D4)<0.01,"Khớp","Lệch") -> Khớp
A5: File UV (báo cáo ngày) | B5: 2280 | C5: =SUMIFS('S32 5-10 đến 29-10'!$Q$3:$Q$103,'S32 5-10 đến 29-10'!$R$3:$R$103,A5) -> 2280 | D5: =C5-B5 -> 0 | E5: =IF(ABS(D5)<0.01,"Khớp","Lệch") -> Khớp
A6: File UV (phát sinh) | B6: 22.5 | C6: =SUMIFS('S32 5-10 đến 29-10'!$Q$3:$Q$103,'S32 5-10 đến 29-10'!$R$3:$R$103,A6) -> 22.5 | D6: =C6-B6 -> 0 | E6: =IF(ABS(D6)<0.01,"Khớp","Lệch") -> Khớp
A7: File Ép nóng | B7: 103 | C7: =SUMIFS('S32 5-10 đến 29-10'!$Q$3:$Q$103,'S32 5-10 đến 29-10'!$R$3:$R$103,A7) -> 103 | D7: =C7-B7 -> 0 | E7: =IF(ABS(D7)<0.01,"Khớp","Lệch") -> Khớp
A8: File Veneer | B8: 72.3333 | C8: =SUMIFS('S32 5-10 đến 29-10'!$Q$3:$Q$103,'S32 5-10 đến 29-10'!$R$3:$R$103,A8) -> 72.333333 | D8: =C8-B8 -> 3.3333333e-05 | E8: =IF(ABS(D8)<0.01,"Khớp","Lệch") -> Khớp
A9: File sửa hàng MAC | B9: 17.8333 | C9: =SUMIFS('S32 5-10 đến 29-10'!$Q$3:$Q$103,'S32 5-10 đến 29-10'!$R$3:$R$103,A9) -> 17.6 | D9: =C9-B9 -> -0.2333 | E9: =IF(ABS(D9)<0.01,"Khớp","Lệch") -> Lệch
A10: Hình: thợ sơn | B10: 1728 | C10: =SUMIFS('S32 5-10 đến 29-10'!$Q$3:$Q$103,'S32 5-10 đến 29-10'!$R$3:$R$103,A10) -> 1728 | D10: =C10-B10 -> 0 | E10: =IF(ABS(D10)<0.01,"Khớp","Lệch") -> Khớp
A11: Hình: cào cước | B11: 55 | C11: =SUMIFS('S32 5-10 đến 29-10'!$Q$3:$Q$103,'S32 5-10 đến 29-10'!$R$3:$R$103,A11) -> 55 | D11: =C11-B11 -> 0 | E11: =IF(ABS(D11)<0.01,"Khớp","Lệch") -> Khớp
A12: Hình: bắn cát | B12: 56 | C12: =SUMIFS('S32 5-10 đến 29-10'!$Q$3:$Q$103,'S32 5-10 đến 29-10'!$R$3:$R$103,A12) -> 56 | D12: =C12-B12 -> 0 | E12: =IF(ABS(D12)<0.01,"Khớp","Lệch") -> Khớp
A13: Hình: INLAY (RESIN) | B13: 84 | C13: =SUMIFS('S32 5-10 đến 29-10'!$Q$3:$Q$103,'S32 5-10 đến 29-10'!$R$3:$R$103,A13) -> 84 | D13: =C13-B13 -> 0 | E13: =IF(ABS(D13)<0.01,"Khớp","Lệch") -> Khớp
A14: Tổng | B14: =SUM(B4:B13) -> 4427.8666 | C14: =SUM(C4:C13) -> 4427.6333 | D14: =SUM(D4:D13) -> -0.23326667 | E14: =IF(ABS(D14)<0.01,"Khớp","Lệch") -> Lệch
A16: Chữ xanh = số lấy từ file/hình nguồn (cột "SỐ GIỜ" hoặc tổng tuần trong báo cáo). Chỉ lấy các dòng từ 05/10/2026 trở đi.

Sheet Chi tiết mã hàng
A1: Ngày | B1: Nguồn | C1: Mã hàng / code | D1: Tên chi tiết | E1: Số lượng
A2: 46300 | B2: File Ép nóng | C2: CZ842F188 | D2: A1-S04 | E2: 10
A3: 46300 | B3: File Ép nóng | C3: CZ842F381 | D3: A1-S04 | E3: 5
A4: 46300 | B4: File Ép nóng | C4: CZ842F409 | D4: A1-S04 | E4: 10
A5: 46300 | B5: File Ép nóng | C5: CE517F992-TOP | D5: A1-S01 | E5: 27
A6: 46300 | B6: File Ép nóng | C6: CE592F1222-TOP | D6: A1-S01-1 | E6: 23
A7: 46301 | B7: File Ép nóng | C7: CE517F992-TOP | D7: A1-S01 | E7: 27
A8: 46301 | B8: File Ép nóng | C8: CE592F1222-TOP | D8: A1-S01-1 | E8: 23
A9: 46305 | B9: File Veneer | C9: code 516 | D9: 320x620 | E9: 50
A10: 46305 | B10: File Veneer | C10: code 231 | D10: 320x620 | E10: 100
A11: 46307 | B11: File UV (phát sinh) | C11: RH11-1119-0129-41797 | D11: SLAT | E11: 13
A12: 46307 | B12: File UV (phát sinh) | C12: RH11-1179-0129-40474 | D12: SLAT | E12: 13
A13: 46307 | B13: File UV (phát sinh) | C13: RH11-4136-0129-40505 | D13: SLAT | E13: 13
... A39: 46318 | B39: File sửa hàng MAC | C39: AR15-1016-892 | D39: TOP A1 | E39: 65
A40: 46319 | B40: File Veneer | C40: code 239 | D40: veneer lỗi | E40: 130m2
A41: 46319 | B41: Hình: bắn cát | C41: RH1792 | D41: CHÂN | E41: 274
A42: 46319 | B42: Hình: bắn cát | C42: RH2250 | D42: CHÂN | E42: 356
A43: 46319 | B43: Hình: bắn cát | C43: RH3023 | D43: CHÂN | E43: 2
A44: 46319 | B44: Hình: bắn cát | C44: RH772 | D44: CHÂN | E44: 100
A45: 46323 | B45: File sửa hàng MAC | C45: RH12-3791 | E45: 19/20 bộ

Sheet Ghi chú review
A1: GHI CHÚ REVIEW - BẢNG S32 (LÀM RIÊNG)
A2: 1. Bảng này CHỈ chứa mã S32, tách hoàn toàn khỏi bảng P20/P26/P22/A2 (không lẫn mã khác). Khi bạn cập nhật, tôi giữ nguyên nguyên tắc này.
A3: 2. Nguồn: 5 file trong gói zip (lấy bản mới nhất mỗi loại: Beam saw bản 29/10, UV bản 24/10, Ép nóng bản 29/10, Veneer bản mới nhất 24/10, file sửa hàng MAC Mr.Hiệp) và 6 hình (thợ sơn, cào cước, bắn cát tuần 42 và tuần 43). Chỉ lấy dòng từ 05/10 đến 29/10. Ép nóng (đến 6/10) chưa có số liệu mới. UV báo cáo ngày nay có đến 24/10; phát sinh đến 13/10.
A4: 3. Tất cả giờ công trong bảng khớp với số giờ trong nguồn (sheet "Đối chiếu nguồn"). Tổng giờ công xem sheet "Đối chiếu nguồn".
A5: 4. UV báo cáo ngày: báo cáo ghi giờ = 8 giờ x HC làm việc + 4 giờ x HC tăng ca. Tôi tách mỗi ngày thành 2 dòng (ca thường 7:30-15:30; tăng ca 15:30-19:30) để ra đúng số giờ báo cáo. Tiền lệ trong file ghi 1 dòng/ngày (7:30-19:30), cần xác nhận cách ghi.
A6: 5. UV Chủ nhật 11/10: có 9 người làm 8 giờ (72 giờ). Cần xác nhận có nhập Chủ nhật không (tô cam).
A7: 6. UV báo cáo ngày (file mới 24/10): từ 12/10 đến 24/10 là các dòng mới; 5/10-11/10 không đổi. File có nhiều khối W42 bị lặp (12/10-18/10 xuất hiện 2 lần, giống hệt nhau), bảng chỉ tính một lần. Chủ nhật 18/10 và 25/10 không có HC làm việc nên không ghi. UV phát sinh 12/10 có 23 mã hàng SLAT nhưng chỉ 2 dòng có giờ (HC 1, 9:30-20:00 và 7:30-15:00); danh sách mã ở sheet "Chi tiết mã hàng". Bộ phận ghi "QC" (báo cáo ghi "QC A HIẾU"), cần xác nhận. Sheet UV phát sinh chỉ đổi nhãn tuần W41 thành W42.
A8: 7. Beam saw (bản 29/10, 30 dòng): 23 dòng có giờ từ 08/10 đến 29/10. Thêm so với bản trước: 24/10 AT733F1463 (TF, 0,1 giờ); 28/10 HS5913F1360 hai dòng (TF, 0,5 + 2,1 giờ); 29/10 ba dòng AT25-1008 (F888, F1089, F535) bộ phận Final machining ghi MACHINING (0,2 giờ mỗi dòng). Cột Charge to "Technical" ghi TECHNICAL FINISHING. 7 dòng "HÀNG BẢNG MÀU" ngày 22/10 vẫn chưa có giờ. Dòng CZ567F09 ngày 20/10 đã sửa 18:15-18:18. 3 dòng ngày 19/10 (18:00-18:07) trên hệ thống đang nhập ngày 18/10, nguồn ghi 19/10. 5 dòng ngày 16/10, 20/10 và 24/10 là "Unassigned" (chưa phân công), cần xác định bộ phận (tô cam).
A9: 8. Ép nóng: 3 nhóm đến 6/10 (5/10 hỗ trợ P1 4 người 16 giờ; 5/10 ép lót 5 người 30 giờ; 6/10 ép chính 5 người 55 giờ) và dòng mới 26/10: AT655F535 chi tiết A5-S02-1, 4 người 7:00-7:30 (2 giờ công), Charge to Unassigned (tô cam, chờ xác định bộ phận). Mỗi nhóm có nhiều mã hàng cùng một ca nên ghi một dòng, mã hàng nối bằng "+" (xem sheet Chi tiết).
A10: 9. Veneer (làm mẫu): 10/10 (2 người 9:00-10:30, 3 giờ, TF), 15/10 (1 người 8:00-8:20, ME) và 20/10 (code 191: 1 người 9:00-9:50, TF; walnut cắt ghép RH21-2184-492: 2 người 10:00-11:15, nguồn ghi Charge to "bs lại" nên bộ phận cần xác nhận, tô cam; code 014: 1 người 10:00-10:40, ME). Khu vực ghi RC - PANEL (Raw Cutting, người dùng xác nhận 20/10).
A11: 10. Thợ sơn: tuần 42 (12 người, 7:30-19:30 từ 12/10 đến 16/10, thứ Bảy 17/10 7:30-15:30 = 816 giờ) và tuần 43 (12 người, 7:30-19:30 từ 19/10 đến 23/10, thứ Bảy 24/10 và Chủ nhật 25/10 mỗi ngày 7:30-15:30 = 912 giờ; báo cáo tuần 43 ghi CN làm 8 giờ). Cào cước: 16/10 (9 giờ, giờ 15:00-20:00 có thể là dự kiến); 20/10 RH109F1 2 người, báo cáo ghi 7:30-20:00 nhưng 24 giờ nên bảng ghi 7:30-19:30 (tô vàng); 24/10 RH133F1 2 người 8:00-16:00 (16 giờ); 25/10 (Chủ nhật) RH133F1 2 người 8:00-11:00 (6 giờ). Bắn cát: 15/10 4 người ghi 7:00-15:00 để đúng 8 giờ/người (báo cáo ghi 7:00-16:00); 24/10 3 người 8:00-16:00 (24 giờ, 4 mã hàng RH1792 274, RH2250 356, RH3023 2, RH772 100, gộp 1 dòng). Các dòng Chủ nhật 25/10 (thợ sơn 96 giờ, cào cước 6 giờ) tô cam, cần xác nhận có nhập Chủ nhật không.
A12: 11. Tên bộ phận và khu vực đã đổi theo dropdown hệ thống (lấy từ file xuất 20/10): FINISHING, TECHNICAL FINISHING, OTHERS (INVESTIGATE) cho hỗ trợ P1, QA/QC/TESTING, SUBCON, MACHINING, ME; khu vực Raw Cutting và Assembly. Cách ghi này theo người nhập trước (Hùng, Tiến).
... A15: 14. Beam saw 22/10: 7 dòng "HÀNG BẢNG MÀU" (W0114F08, W0276F03, W1981F1055, W2629F1222, W0164F01 x2, W2446F1200) chưa có giờ bắt đầu/kết thúc trong nguồn nên chưa đưa vào bảng (0 giờ). Cần hỏi giờ nếu muốn nhập. Hàng bảng màu theo tiền lệ ghi bộ phận TECHNICAL FINISHING.
